Workbook
Name _______CAP10: {"LC",#N/A,FALSE,"FC-15 Cap Expend"}
Name _______new3: {"FY98Q1 nvs",#N/A,FALSE,"FY98 - Q1";"FY98Q2 nvs",#N/A,FALSE,"FY98 - Q2";"FY98Q3 nvs",#N/A,FALSE,"FY98 - Q3";"FY98Q4 nvs",#N/A,FALSE,"FY98 - Q4"}
Name _______new4: {"INPUT",#N/A,FALSE,"REVENUE AND GM ";"CONTROL",#N/A,FALSE,"REVENUE AND GM ";"SWITCH",#N/A,FALSE,"REVENUE AND GM ";"OUTPUT",#N/A,FALSE,"REVENUE AND GM ";"TOTAL",#N/A,FALSE,"REVENUE AND GM "}
Name _______new5: {"FY97Total",#N/A,FALSE,"FY97 - Total";"FY98Total",#N/A,FALSE,"FY98 - Total"}
Name _______new6: {"FY97Q1",#N/A,FALSE,"FY97 - Q1";"FY97Q2",#N/A,FALSE,"FY97 - Q2";"FY97Q3",#N/A,FALSE,"FY97 - Q3";"FY97Q4",#N/A,FALSE,"FY97 - Q4"}
Name ______CAP10: {"LC",#N/A,FALSE,"FC-15 Cap Expend"}
Name ______DP6434: {"TOTALDPAK",#N/A,FALSE,"DPAK PRODUCTION";"HADPAK",#N/A,FALSE,"DPAK PRODUCTION";"PSIDPAK",#N/A,FALSE,"DPAK PRODUCTION"}
Name ______new3: {"FY98Q1 nvs",#N/A,FALSE,"FY98 - Q1";"FY98Q2 nvs",#N/A,FALSE,"FY98 - Q2";"FY98Q3 nvs",#N/A,FALSE,"FY98 - Q3";"FY98Q4 nvs",#N/A,FALSE,"FY98 - Q4"}
Name ______new4: {"INPUT",#N/A,FALSE,"REVENUE AND GM ";"CONTROL",#N/A,FALSE,"REVENUE AND GM ";"SWITCH",#N/A,FALSE,"REVENUE AND GM ";"OUTPUT",#N/A,FALSE,"REVENUE AND GM ";"TOTAL",#N/A,FALSE,"REVENUE AND GM "}
Name ______new5: {"FY97Total",#N/A,FALSE,"FY97 - Total";"FY98Total",#N/A,FALSE,"FY98 - Total"}
Name ______new6: {"FY97Q1",#N/A,FALSE,"FY97 - Q1";"FY97Q2",#N/A,FALSE,"FY97 - Q2";"FY97Q3",#N/A,FALSE,"FY97 - Q3";"FY97Q4",#N/A,FALSE,"FY97 - Q4"}
Name ______TEM6434: {"ALLOCATION1",#N/A,FALSE,"EXPENSE ALLOCATIONS";"ALLOCATION2",#N/A,FALSE,"EXPENSE ALLOCATIONS";"ALLOCATION3",#N/A,FALSE,"EXPENSE ALLOCATIONS";"ALLOCATION4",#N/A,FALSE,"EXPENSE ALLOCATIONS"}
Name _____a2: {#N/A,#N/A,FALSE,"Sheet1"}
Name _____a3: {#N/A,#N/A,FALSE,"Sheet1"}
Name _____ALL6434: {"ALLOCATION1",#N/A,FALSE,"EXPENSE ALLOCATIONS";"ALLOCATION2",#N/A,FALSE,"EXPENSE ALLOCATIONS";"ALLOCATION3",#N/A,FALSE,"EXPENSE ALLOCATIONS";"ALLOCATION4",#N/A,FALSE,"EXPENSE ALLOCATIONS"}
Name _____CAP10: {"LC",#N/A,FALSE,"FC-15 Cap Expend"}
Name _____DP6434: {"TOTALDPAK",#N/A,FALSE,"DPAK PRODUCTION";"HADPAK",#N/A,FALSE,"DPAK PRODUCTION";"PSIDPAK",#N/A,FALSE,"DPAK PRODUCTION"}
Name _____new2: {"FY97Q1 nvs",#N/A,FALSE,"FY97 - Q1";"FY97Q2 nvs",#N/A,FALSE,"FY97 - Q2";"FY97Q3 nvs",#N/A,FALSE,"FY97 - Q3";"FY97Q4 nvs",#N/A,FALSE,"FY97 - Q4"}
Name _____new3: {"FY98Q1 nvs",#N/A,FALSE,"FY98 - Q1";"FY98Q2 nvs",#N/A,FALSE,"FY98 - Q2";"FY98Q3 nvs",#N/A,FALSE,"FY98 - Q3";"FY98Q4 nvs",#N/A,FALSE,"FY98 - Q4"}
Name _____new4: {"INPUT",#N/A,FALSE,"REVENUE AND GM ";"CONTROL",#N/A,FALSE,"REVENUE AND GM ";"SWITCH",#N/A,FALSE,"REVENUE AND GM ";"OUTPUT",#N/A,FALSE,"REVENUE AND GM ";"TOTAL",#N/A,FALSE,"REVENUE AND GM "}
Name _____new5: {"FY97Total",#N/A,FALSE,"FY97 - Total";"FY98Total",#N/A,FALSE,"FY98 - Total"}
Name _____new6: {"FY97Q1",#N/A,FALSE,"FY97 - Q1";"FY97Q2",#N/A,FALSE,"FY97 - Q2";"FY97Q3",#N/A,FALSE,"FY97 - Q3";"FY97Q4",#N/A,FALSE,"FY97 - Q4"}
Name _____TEM6434: {"ALLOCATION1",#N/A,FALSE,"EXPENSE ALLOCATIONS";"ALLOCATION2",#N/A,FALSE,"EXPENSE ALLOCATIONS";"ALLOCATION3",#N/A,FALSE,"EXPENSE ALLOCATIONS";"ALLOCATION4",#N/A,FALSE,"EXPENSE ALLOCATIONS"}
Name ____a2: {#N/A,#N/A,FALSE,"Sheet1"}
Name ____a3: {#N/A,#N/A,FALSE,"Sheet1"}
Name ____ALL6434: {"ALLOCATION1",#N/A,FALSE,"EXPENSE ALLOCATIONS";"ALLOCATION2",#N/A,FALSE,"EXPENSE ALLOCATIONS";"ALLOCATION3",#N/A,FALSE,"EXPENSE ALLOCATIONS";"ALLOCATION4",#N/A,FALSE,"EXPENSE ALLOCATIONS"}
Name ____CAP10: {"LC",#N/A,FALSE,"FC-15 Cap Expend"}
Name ____DP6434: {"TOTALDPAK",#N/A,FALSE,"DPAK PRODUCTION";"HADPAK",#N/A,FALSE,"DPAK PRODUCTION";"PSIDPAK",#N/A,FALSE,"DPAK PRODUCTION"}
Name ____new2: {"FY97Q1 nvs",#N/A,FALSE,"FY97 - Q1";"FY97Q2 nvs",#N/A,FALSE,"FY97 - Q2";"FY97Q3 nvs",#N/A,FALSE,"FY97 - Q3";"FY97Q4 nvs",#N/A,FALSE,"FY97 - Q4"}
Name ____new3: {"FY98Q1 nvs",#N/A,FALSE,"FY98 - Q1";"FY98Q2 nvs",#N/A,FALSE,"FY98 - Q2";"FY98Q3 nvs",#N/A,FALSE,"FY98 - Q3";"FY98Q4 nvs",#N/A,FALSE,"FY98 - Q4"}
Name ____new4: {"INPUT",#N/A,FALSE,"REVENUE AND GM ";"CONTROL",#N/A,FALSE,"REVENUE AND GM ";"SWITCH",#N/A,FALSE,"REVENUE AND GM ";"OUTPUT",#N/A,FALSE,"REVENUE AND GM ";"TOTAL",#N/A,FALSE,"REVENUE AND GM "}
Name ____new5: {"FY97Total",#N/A,FALSE,"FY97 - Total";"FY98Total",#N/A,FALSE,"FY98 - Total"}
Name ____new6: {"FY97Q1",#N/A,FALSE,"FY97 - Q1";"FY97Q2",#N/A,FALSE,"FY97 - Q2";"FY97Q3",#N/A,FALSE,"FY97 - Q3";"FY97Q4",#N/A,FALSE,"FY97 - Q4"}
Name ____TEM6434: {"ALLOCATION1",#N/A,FALSE,"EXPENSE ALLOCATIONS";"ALLOCATION2",#N/A,FALSE,"EXPENSE ALLOCATIONS";"ALLOCATION3",#N/A,FALSE,"EXPENSE ALLOCATIONS";"ALLOCATION4",#N/A,FALSE,"EXPENSE ALLOCATIONS"}
Name ___a2: {#N/A,#N/A,FALSE,"Sheet1"}
Name ___a3: {#N/A,#N/A,FALSE,"Sheet1"}
Name ___ALL6434: {"ALLOCATION1",#N/A,FALSE,"EXPENSE ALLOCATIONS";"ALLOCATION2",#N/A,FALSE,"EXPENSE ALLOCATIONS";"ALLOCATION3",#N/A,FALSE,"EXPENSE ALLOCATIONS";"ALLOCATION4",#N/A,FALSE,"EXPENSE ALLOCATIONS"}
Name ___CAP10: {"LC",#N/A,FALSE,"FC-15 Cap Expend"}
Name ___DP6434: {"TOTALDPAK",#N/A,FALSE,"DPAK PRODUCTION";"HADPAK",#N/A,FALSE,"DPAK PRODUCTION";"PSIDPAK",#N/A,FALSE,"DPAK PRODUCTION"}
Name ___new2: {"FY97Q1 nvs",#N/A,FALSE,"FY97 - Q1";"FY97Q2 nvs",#N/A,FALSE,"FY97 - Q2";"FY97Q3 nvs",#N/A,FALSE,"FY97 - Q3";"FY97Q4 nvs",#N/A,FALSE,"FY97 - Q4"}
Name ___new3: {"FY98Q1 nvs",#N/A,FALSE,"FY98 - Q1";"FY98Q2 nvs",#N/A,FALSE,"FY98 - Q2";"FY98Q3 nvs",#N/A,FALSE,"FY98 - Q3";"FY98Q4 nvs",#N/A,FALSE,"FY98 - Q4"}
Name ___new4: {"INPUT",#N/A,FALSE,"REVENUE AND GM ";"CONTROL",#N/A,FALSE,"REVENUE AND GM ";"SWITCH",#N/A,FALSE,"REVENUE AND GM ";"OUTPUT",#N/A,FALSE,"REVENUE AND GM ";"TOTAL",#N/A,FALSE,"REVENUE AND GM "}
Name ___new5: {"FY97Total",#N/A,FALSE,"FY97 - Total";"FY98Total",#N/A,FALSE,"FY98 - Total"}
Name ___new6: {"FY97Q1",#N/A,FALSE,"FY97 - Q1";"FY97Q2",#N/A,FALSE,"FY97 - Q2";"FY97Q3",#N/A,FALSE,"FY97 - Q3";"FY97Q4",#N/A,FALSE,"FY97 - Q4"}
Name ___TEM6434: {"ALLOCATION1",#N/A,FALSE,"EXPENSE ALLOCATIONS";"ALLOCATION2",#N/A,FALSE,"EXPENSE ALLOCATIONS";"ALLOCATION3",#N/A,FALSE,"EXPENSE ALLOCATIONS";"ALLOCATION4",#N/A,FALSE,"EXPENSE ALLOCATIONS"}
Name __123Graph_A: #REF!
Name __123Graph_ACURRENT: #REF!
Name __123Graph_APROCEEDS: #REF!
Name __123Graph_ASALESTREND: #REF!
Name __123Graph_B: #REF!
Name __123Graph_BCURRENT: #REF!
Name __123Graph_BPROCEEDS: #REF!
Name __123Graph_C: #REF!
Name __123Graph_CPROCEEDS: #REF!
Name __123Graph_D: #REF!
Name __123Graph_E: #REF!
Name __123Graph_F: #REF!
Name __123Graph_LBL_ASALESTREND: #REF!
Name __123Graph_X: #REF!
Name __123Graph_XCURRENT: #REF!

Sheet DEFINITIONS
B2: DEFINITION OF EACH LINE ITEM
A3: x | B3: OPERATING CASH INFLOWS
B4: Operating Cash Receipts
B5: Customer Cash Receipts from A/R | C5: Pulled from AR Aging report
B6: Customer Forecasted Receipts from Backlog | C6: Receipts for products/services that are in backlog and sale is not complete; pulled from ERP/MRP/Other infrastructure
B7: Customer Forecasted Receipts from Sales Forecast | C7: Forecasted receipts from products / services in pipeline; pulled from Salesforce and/or sales team reports built off Salesforce
B8: Other, non-customer related inflows | C8: Non-customer related inflows; this could include insurance payments, legal settlements, asset disposal, etc.
B9: TOTAL INCOMING CASH
A11: x | B11: OPERATING CASH DISBURSEMENTS
B12: Must Pays
B13: Wages and benefits | C13: Weekly payroll (Salary + all benefits + bonus accruals + etc.); pulled from payroll systems
B14: Rent | C14: Rental invoice (vs. accrued rent)
B15: Insurance | C15: Insurance Invoice
B16: Sales Tax Expense | C16: Sales tax expense - payment cadence and date varies per nexus
B17: Credit Card Expense | C17: Credit card expense - payment is on autopayment
B18: Other | C18: Other, non-material weekly, monthly, or quarterly 'must pays'
B19: Total Must Pay
B20: Accounts Payable
B21: Payables by week | C21: Pulled from AP Aging report
B22: Recurring Non Inventory Payables not in Aging report | C22: Payables that recur that are not related to inventory and do not show up in AP aging report
B23: Estimated Inventory AP from Open Purchase Orders | C23: Forecast of cash outlays for AP on open purchase orders
B24: Estimated Inventory AP from MRP estimated purchases | C24: Forecast of cash outlays for AP on orders in MRP and/or forecasted for following 13 weeks
B25: Total Accounts Payable
B26: TOTAL OPERATING CASH OUTFLOWS
A28: x | B28: OPERATING CASH FLOW (excl. financing activities) | C28: Forecasted cashflow from operations - does not include financing activities
A30: x | B30: FUNDING REQUEST
B31: Tide Rock Capital Funding (LT Notes Payable) | C31: LT funding request for CapEx
B32: Tide Rock Cashflow Funding (ST Notes Payable) | C32: ST funding request for Working Capital
B33: TOTAL FUNDING REQUEST
A35: x | B35: NON OPERATING CASH DISBURSEMENTS
B36: Tide Rock Notes Repayment | C36: Identify repayment plan and months for payment
B37: Tide Rock Interest Payments | C37: Tide Rock interest payments on outstanding line of credit
B38: Tide Rock Distributions (including MPs) | C38: Tide Rock distribution payments
A40: x | B40: NET CASH FLOW | C40: Net cashflow when including financing activities
B42: Beginning Bank Balance | C42: Cash balance across all operating accounts
B43: Outstanding checks | C43: Outstanding checks that have been sent but not cashed by time of forecast
A45: x | B45: ENDING BOOK BALANCE | C45: Ending bank balance across all operating accounts

Sheet CURRENT FORECAST START DATE
B4: Forecast Start Date | C4: 45971
C5: This should be the Monday of the first week you are forecasting (i.e., the Monday you send this to your accounting contact)

Sheet Weekly Spend
O3: =IF(O8='CURRENT FORECAST START DATE'!$C$4,"CURRENT WEEK","") | P3: =IF(P8='CURRENT FORECAST START DATE'!$C$4,"CURRENT WEEK","") | Q3: =IF(Q8='CURRENT FORECAST START DATE'!$C$4,"CURRENT WEEK","") | R3: =IF(R8='CURRENT FORECAST START DATE'!$C$4,"CURRENT WEEK","") | S3: =IF(S8='CURRENT FORECAST START DATE'!$C$4,"CURRENT WEEK","") | T3: =IF(T8='CURRENT FORECAST START DATE'!$C$4,"CURRENT WEEK","") | U3: =IF(U8='CURRENT FORECAST START DATE'!$C$4,"CURRENT WEEK","") | V3: =IF(V8='CURRENT FORECAST START DATE'!$C$4,"CURRENT WEEK","") | ... CV3: =IF(CV8='CURRENT FORECAST START DATE'!$C$4,"CURRENT WEEK","")
H4: Labor | J4: Labor | L4: =H4 -> Labor | M4: =I4 -> 0 | O4: =J4 -> Labor | P4: =K4 -> 0 | Q4: =L4 -> Labor | R4: =M4 -> 0 | S4: =O4 -> Labor | T4: =P4 -> 0 | U4: =Q4 -> Labor | V4: =R4 -> 0 | W4: =S4 -> Labor | X4: =T4 -> 0 | Y4: =U4 -> Labor | Z4: =V4 -> 0 | ... CV4: =CR4 -> 0
G5: =WEEKNUM(G7) -> 14 | H5: =WEEKNUM(H7) -> 14 | I5: =WEEKNUM(I7) -> 18 | J5: =WEEKNUM(J7)&YEAR(J7) -> 182025 | K5: =WEEKNUM(K7)&YEAR(K7) -> 182025 | L5: =WEEKNUM(L7)&YEAR(L7) -> 182025 | M5: =WEEKNUM(M7)&YEAR(M7) -> 222025 | O5: =WEEKNUM(O7)&YEAR(O7) -> 222025 | P5: =WEEKNUM(P7)&YEAR(P7) -> 222025 | Q5: =WEEKNUM(Q7)&YEAR(Q7) -> 222025 | R5: =WEEKNUM(R7)&YEAR(R7) -> 272025 | S5: =WEEKNUM(S7)&YEAR(S7) -> 272025 | T5: =WEEKNUM(T7)&YEAR(T7) -> 272025 | U5: =WEEKNUM(U7)&YEAR(U7) -> 272025 | V5: =WEEKNUM(V7)&YEAR(V7) -> 272025 | ... CV5: =WEEKNUM(CV7)&YEAR(CV7) -> 532026
G6: =WEEKNUM(G8) -> 13 | H6: =WEEKNUM(H8) -> 14 | I6: =WEEKNUM(I8) -> 15 | J6: =WEEKNUM(J8)&YEAR(J8) -> 162025 | K6: =WEEKNUM(K8)&YEAR(K8) -> 172025 | L6: =WEEKNUM(L8)&YEAR(L8) -> 182025 | M6: =WEEKNUM(M8)&YEAR(M8) -> 192025 | O6: =WEEKNUM(O8)&YEAR(O8) -> 202025 | P6: =WEEKNUM(P8)&YEAR(P8) -> 212025 | Q6: =WEEKNUM(Q8)&YEAR(Q8) -> 222025 | R6: =WEEKNUM(R8)&YEAR(R8) -> 232025 | S6: =WEEKNUM(S8)&YEAR(S8) -> 242025 | T6: =WEEKNUM(T8)&YEAR(T8) -> 252025 | U6: =WEEKNUM(U8)&YEAR(U8) -> 262025 | V6: =WEEKNUM(V8)&YEAR(V8) -> 272025 | ... CV6: =WEEKNUM(CV8)&YEAR(CV8) -> 532026
F7: Month End | G7: =EOMONTH(G8,0) -> 45747 | H7: =EOMONTH(H8,0) -> 45747 | I7: =EOMONTH(I8,0) -> 45777 | J7: =EOMONTH(J8,0) -> 45777 | K7: =EOMONTH(K8,0) -> 45777 | L7: =EOMONTH(L8,0) -> 45777 | M7: =EOMONTH(M8,0) -> 45808 | N7: 2025 YTG | O7: =EOMONTH(O8,0) -> 45808 | P7: =EOMONTH(P8,0) -> 45808 | Q7: =EOMONTH(Q8,0) -> 45808 | R7: =EOMONTH(R8,0) -> 45838 | S7: =EOMONTH(S8,0) -> 45838 | T7: =EOMONTH(T8,0) -> 45838 | U7: =EOMONTH(U8,0) -> 45838 | V7: =EOMONTH(V8,0) -> 45838 | ... CV7: =EOMONTH(CV8,0) -> 46387
F8: Week Start | G8: 45740 | H8: =+G8+7 -> 45747 | I8: =+H8+7 -> 45754 | J8: =+I8+7 -> 45761 | K8: =+J8+7 -> 45768 | L8: =+K8+7 -> 45775 | M8: =+L8+7 -> 45782 | O8: =+M8+7 -> 45789 | P8: =+O8+7 -> 45796 | Q8: =+P8+7 -> 45803 | R8: =+Q8+7 -> 45810 | S8: =+R8+7 -> 45817 | T8: =+S8+7 -> 45824 | U8: =+T8+7 -> 45831 | V8: =+U8+7 -> 45838 | W8: =+V8+7 -> 45845 | ... CV8: =+CU8+7 -> 46384
A9: Source | B9: Order | C9: ID | D9: Vendor | E9: Type | F9: Category | G9: =G23 -> 0 | H9: =H23 -> 0 | I9: =I23 -> 0 | J9: =J23 -> 0 | K9: =K23 -> 0 | L9: =L23 -> 0 | M9: =M23 -> 5000 | O9: =O23 -> 0 | P9: =P23 -> 0 | Q9: =Q23 -> 0 | R9: =R23 -> 0 | S9: =S23 -> 0 | T9: =T23 -> 0 | U9: =U23 -> 100 | V9: =V23 -> 0 | ... AI9: =AI23 -> 0 | AJ9: hju | AK9: =AK23 -> 0 | AL9: =AL23 -> 15000 | AM9: =AM23 -> 0 | AN9: =AN23 -> 0 | AO9: =AO23 -> 10378 | AP9: =AP23 -> 0 | AQ9: =AQ23 -> 0 | AR9: =AR23 -> 0 | ... CV9: =CV23 -> 0
A10: ST Cash File (Manual) | B10: =_xlfn.SINGLE(_xlfn.XLOOKUP(F10, $F$87:$F$95, $E$87:$E$95)) -> 6 | C10: K31 | D10: Askey | E10: Q20 | F10: Inventory | H10: 530470 | N10: =SUMIF($O$8:$AV$8,">="&'CURRENT FORECAST START DATE'!$C$4,'Weekly Spend'!O10:AV10) -> 0 | O10: 561009 | P10: 0 | Q10: 0 | R10: 0 | S10: 0 | T10: 0 | U10: 0 | V10: 0 | W10: 0 | X10: 0 | Y10: 294525 | AA10: 0 | AB10: 0 | AC10: 0 | AD10: 0 | AE10: 0 | AF10: 0 | AG10: 0 | AH10: 0 | AI10: 0 | AJ10: 0 | AK10: 0 | AL10: 0 | AM10: 0 | AN10: 0 | AO10: 0 | AP10: 0 | AQ10: 0 | AR10: 0 | AS10: 0 | AT10: 0 | AU10: 0 | AV10: 0 | AW10: 0 | AX10: 0 | AY10: 0 | AZ10: 0 | BA10: 0 | BB10: 0 | BC10: 0 | BD10: 0 | BE10: 0 | BF10: 0 | BG10: 0 | BH10: 0 | BI10: 0 | BJ10: 0 | BK10: 0 | BL10: 0 | BM10: 0 | BN10: 0 | BO10: 0 | BP10: 0 | BQ10: 0 | BR10: 0 | BS10: 0 | BT10: 0 | BU10: 0 | BV10: 0 | BW10: 0 | BX10: 0 | BY10: 0 | BZ10: 0 | CA10: 0 | CB10: 0 | CC10: 0 | CD10: 0 | CE10: 0 | CF10: 0 | CG10: 0 | CH10: 0 | CI10: 0 | CJ10: 0 | CK10: 0 | CL10: 0 | CM10: 0 | CN10: 0 | CO10: 0 | CP10: 0 | CQ10: 0 | CR10: 0 | CS10: 0 | CT10: 0 | CU10: 0 | CV10: 0
D11: Askey | E11: Q20RoW | F11: Inventory | N11: =SUMIF($O$8:$AV$8,">="&'CURRENT FORECAST START DATE'!$C$4,'Weekly Spend'!O11:AV11) -> 0 | O11: 0 | P11: 0 | Q11: 0 | R11: 0 | S11: 0 | T11: 0 | U11: 0 | V11: 0 | W11: 0 | X11: 0 | Y11: 0 | Z11: 0 | AA11: 0 | AB11: 0 | AC11: 0 | AD11: 0 | AE11: 0 | AF11: 0 | AG11: 0 | AH11: 0 | AI11: 0 | AJ11: 0 | AK11: 0 | AL11: 0 | AM11: 0 | AN11: 0 | AO11: 0 | AP11: 0 | AQ11: 0 | AR11: 0 | AS11: 0 | AT11: 0 | AU11: 0 | AV11: 0 | AW11: 0 | AX11: 0 | AY11: 0 | AZ11: 0 | BA11: 0 | BB11: 0 | BC11: 0 | BD11: 0 | BE11: 0 | BF11: 0 | BG11: 0 | BH11: 0 | BI11: 0 | BJ11: 0 | BK11: 0 | BL11: 0 | BM11: 0 | BN11: 0 | BO11: 0 | BP11: 0 | BQ11: 0 | BR11: 0 | BS11: 0 | BT11: 0 | BU11: 0 | BV11: 0 | BW11: 0 | BX11: 0 | BY11: 0 | BZ11: 0 | CA11: 0 | CB11: 0 | CC11: 0 | CD11: 0 | CE11: 0 | CF11: 0 | CG11: 0 | CH11: 0 | CI11: 0 | CJ11: 0 | CK11: 0 | CL11: 0 | CM11: 0 | CN11: 0 | CO11: 0 | CP11: 0 | CQ11: 0 | CR11: 0 | CS11: 0 | CT11: 0 | CU11: 0 | CV11: 0
A12: ST Cash File (Manual) | B12: =_xlfn.SINGLE(_xlfn.XLOOKUP(F12, $F$87:$F$95, $E$87:$E$95)) -> 6 | C12: K30 | D12: T&W | E12: PO3 | F12: Inventory | J12: 365500 | M12: 0 | N12: =SUMIF($O$8:$AV$8,">="&'CURRENT FORECAST START DATE'!$C$4,'Weekly Spend'!O12:AV12) -> 29050 | O12: 0 | P12: 0 | Q12: 0 | R12: 0 | S12: =446000+35000 -> 481000 | T12: 0 | U12: 0 | V12: 0 | W12: 0 | X12: 0 | Y12: 0 | Z12: 0 | AA12: 0 | AB12: 0 | AC12: 0 | AD12: 0 | AE12: 0 | AF12: 0 | AG12: 0 | AH12: 0 | AI12: 0 | AJ12: 0 | AK12: 0 | AL12: 0 | AM12: 0 | AN12: 0 | AO12: 29050 | AP12: 0 | AQ12: 0 | AR12: 0 | AS12: 0 | AT12: 0 | AU12: 0 | AV12: 0 | AW12: 0 | AY12: 0 | AZ12: 35000 | BA12: 0 | BB12: 0 | BC12: 0 | BD12: 0 | BE12: 0 | BF12: 0 | BG12: 0 | BH12: 0 | BI12: 0 | BJ12: 0 | BK12: 0 | BL12: 0 | BM12: 0 | BN12: 0 | BO12: 0 | BP12: 0 | BQ12: 0 | BR12: 0 | BS12: 0 | BT12: 0 | BU12: 0 | BV12: 0 | BW12: 0 | BX12: 0 | BY12: 0 | BZ12: 0 | CA12: 0 | CB12: 0 | CC12: 0 | CD12: 0 | CE12: 0 | CF12: 0 | CG12: 0 | CH12: 0 | CI12: 0 | CJ12: 0 | CK12: 0 | CL12: 0 | CM12: 0 | CN12: 0 | CO12: 0 | CP12: 0 | CQ12: 0 | CR12: 0 | CS12: 0 | CT12: 0 | CU12: 0 | CV12: 0
A13: ST Cash File (Manual) | B13: =_xlfn.SINGLE(_xlfn.XLOOKUP(F13, $F$87:$F$95, $E$87:$E$95)) -> 6 | C13: K35 | D13: Compal (CBN) | E13: B15 Inventory | F13: Inventory | N13: =SUMIF($O$8:$AV$8,">="&'CURRENT FORECAST START DATE'!$C$4,'Weekly Spend'!O13:AV13) -> 17000 | O13: 0 | P13: 0 | Q13: 0 | R13: 0 | S13: 0 | T13: 0 | U13: 0 | V13: 0 | W13: 0 | X13: 189950 | Y13: 0 | Z13: 0 | AA13: 0 | AB13: 0 | AC13: =56500+313466 -> 369966 | AE13: 0 | AH13: 0 | AI13: 14000 | AJ13: 0 | AK13: 0 | AL13: 0 | AN13: 14000 | AO13: 0 | AP13: 0 | AQ13: =200*85 -> 17000 | AR13: 0 | AS13: 0 | AT13: 0 | AU13: 0 | AW13: 221429 | AX13: =844300-274450 -> 569850 | AY13: 0 | BB13: 0 | BC13: 0 | BD13: =AV13 -> 0 | BE13: =AW13 -> 221429 | BF13: 0 | BG13: 0 | BH13: 0 | BK13: 0 | BL13: 0 | BM13: =BD13 -> 0 | BN13: =BE13 -> 221429 | BO13: 0 | BP13: 0 | BQ13: 0 | BR13: =BJ13 -> 0 | BS13: 0 | BU13: 0 | BV13: 288498 | BW13: 0 | BX13: 0 | BY13: 0 | BZ13: 0 | CA13: 0 | CB13: 0 | CC13: 0 | CD13: 0 | CE13: 0 | CF13: 0 | CG13: 0 | CH13: 0 | CI13: 0 | CJ13: 0 | CK13: 0 | CL13: 0 | CM13: 0 | CN13: 0 | CO13: 0 | CP13: 0 | CQ13: 0 | CR13: 0 | CS13: 0 | CT13: 0 | CU13: 0 | CV13: 0
A14: Atel | D14: Atel | E14: P15 | F14: Inventory | N14: =SUMIF($O$8:$AV$8,">="&'CURRENT FORECAST START DATE'!$C$4,'Weekly Spend'!O14:AV14) -> 38100 | O14: 0 | P14: 0 | Q14: 0 | R14: 0 | S14: 0 | T14: 0 | U14: 0 | V14: 0 | W14: 0 | X14: 0 | Y14: 0 | Z14: 0 | AA14: 0 | AB14: 0 | AC14: 0 | AD14: 0 | AE14: 0 | AF14: 0 | AG14: 0 | AH14: 0 | AI14: 0 | AJ14: 0 | AK14: 0 | AL14: 0 | AM14: 0 | AN14: 0 | AP14: 0 | AQ14: 0 | AR14: 38100 | AS14: 0 | AT14: 0 | AU14: 0 | AV14: 0 | AW14: 0 | AX14: 0 | AZ14: 0 | BA14: 0 | BB14: 0 | BC14: 0 | BD14: 215900 | BE14: 0 | BF14: 0 | BG14: 0 | BH14: 0 | BI14: 0 | BJ14: 0 | BK14: 0 | BL14: 0 | BM14: 0 | BN14: 0 | BO14: 0 | BP14: 0 | BQ14: 0 | BR14: 0 | BS14: 0 | BT14: 0 | BU14: 0 | BV14: 0 | BW14: 0 | BX14: 0 | BY14: 0 | BZ14: 0 | CA14: 0 | CB14: 0 | CC14: 0 | CD14: 0 | CE14: 0 | CF14: 0 | CG14: 0 | CH14: 0 | CI14: 0 | CJ14: 0 | CK14: 0 | CL14: 0 | CM14: 0 | CN14: 0 | CO14: 0 | CP14: 0 | CQ14: 0 | CR14: 0 | CS14: 0 | CT14: 0 | CU14: 0 | CV14: 0
D15: CBN | E15: Q12 | F15: Inventory | N15: =SUMIF($O$8:$AV$8,">="&'CURRENT FORECAST START DATE'!$C$4,'Weekly Spend'!O15:AV15) -> 132000 | O15: 0 | P15: 0 | Q15: 0 | R15: 0 | S15: 0 | T15: 0 | U15: 0 | V15: 0 | W15: 0 | X15: 0 | Y15: 0 | Z15: 0 | AA15: 0 | AB15: 0 | AC15: 0 | AD15: 0 | AE15: 0 | AF15: 0 | AG15: 0 | AH15: 0 | AJ15: 0 | AK15: 0 | AL15: 0 | AN15: 0 | AO15: 0 | AP15: 0 | AR15: 0 | AS15: 0 | AT15: =25% * (26.4*20000) -> 132000 | AU15: 0 | AW15: 0 | AX15: 0 | AY15: 0 | AZ15: 0 | BA15: 0 | BB15: 0 | BC15: 0 | BD15: 0 | BE15: 0 | BF15: 0 | BG15: 0 | BH15: 0 | BI15: 0 | BJ15: 0 | BK15: 0 | BL15: 0 | BM15: 0 | BN15: =75% * (26.4*20000) -> 396000 | BO15: 0 | BP15: 0 | BQ15: 0 | BR15: 0 | BS15: 0 | BT15: 0 | BU15: 0 | BV15: 0 | BW15: 0 | BX15: 0 | BY15: 0 | BZ15: 0 | CA15: 0 | CB15: 0 | CC15: 0 | CD15: 0 | CE15: 0 | CF15: 0 | CG15: 0 | CH15: 0 | CI15: 0 | CJ15: 0 | CK15: 0 | CL15: 0 | CM15: 0 | CN15: 0 | CO15: 0 | CP15: 0 | CQ15: 0 | CR15: 0 | CS15: 0 | CT15: 0 | CU15: 0 | CV15: 0
D16: Salom America | E16: Discount Inventory | F16: Inventory | N16: =SUMIF($O$8:$AV$8,">="&'CURRENT FORECAST START DATE'!$C$4,'Weekly Spend'!O16:AV16) -> 0 | O16: 0 | P16: 0 | Q16: 0 | R16: 0 | S16: 0 | T16: 0 | U16: 450 | V16: 0 | W16: 0 | X16: 0 | Y16: 0 | Z16: 0 | AA16: 0 | AB16: 0 | AC16: 0 | AD16: 0 | AE16: 0 | AF16: 0 | AG16: 0 | AH16: 0 | AI16: 0 | AJ16: 0 | AK16: 0 | AL16: 0 | AM16: 0 | AN16: 0 | AO16: 0 | AP16: 0 | AQ16: 0 | AR16: 0 | AS16: 0 | AT16: 0 | AU16: 0 | AV16: 0 | AW16: 0 | AX16: 0 | AY16: 0 | AZ16: 0 | BA16: 0 | BB16: 0 | BC16: 0 | BD16: 0 | BE16: 0 | BF16: 0 | BG16: 0 | BH16: 0 | BI16: 0 | BJ16: 0 | BK16: 0 | BL16: 0 | BM16: 0 | BN16: 0 | BO16: 0 | BP16: 0 | BQ16: 0 | BR16: 0 | BS16: 0 | BT16: 0 | BU16: 0 | BV16: 0 | BW16: 0 | BX16: 0 | BY16: 0 | BZ16: 0 | CA16: 0 | CB16: 0 | CC16: 0 | CD16: 0 | CE16: 0 | CF16: 0 | CG16: 0 | CH16: 0 | CI16: 0 | CJ16: 0 | CK16: 0 | CL16: 0 | CM16: 0 | CN16: 0 | CO16: 0 | CP16: 0 | CQ16: 0 | CR16: 0 | CS16: 0 | CT16: 0 | CU16: 0 | CV16: 0
A17: ST Cash File (Manual) | D17: Flexport | E17: Shipping | F17: Inventory | J17: 39476.51 | L17: 5000 | N17: =SUMIF($O$8:$AV$8,">="&'CURRENT FORECAST START DATE'!$C$4,'Weekly Spend'!O17:AV17) -> 0 | O17: 0 | P17: 0 | Q17: 0 | R17: 0 | S17: 0 | T17: 0 | U17: 3463 | V17: 0 | W17: =4000+34000 -> 38000 | X17: 0 | Y17: 0 | Z17: 0 | AA17: 0 | AB17: 0 | AC17: 0 | AD17: 0 | AE17: 0 | AF17: 0 | AG17: 0 | AH17: 0 | AI17: 0 | AJ17: 0 | AK17: 0 | AL17: 0 | AM17: 0 | AN17: 0 | AO17: 0 | AP17: 0 | AQ17: 0 | AR17: 0 | AS17: 0 | AT17: 0 | AU17: 0 | AV17: 0 | AW17: 0 | AX17: 0 | AY17: 0 | AZ17: 0 | BA17: 0 | BB17: 0 | BC17: 0 | BD17: 0 | BE17: 0 | BF17: 0 | BG17: 0 | BH17: 0 | BI17: 0 | BJ17: 0 | BK17: 0 | BL17: 0 | BM17: 0 | BN17: 0 | BO17: 0 | BP17: 0 | BQ17: 0 | BR17: 0 | BS17: 0 | BT17: 0 | BU17: 0 | BV17: 0 | BW17: 0 | BX17: 0 | BY17: 0 | BZ17: 0 | CA17: 0 | CB17: 0 | CC17: 0 | CD17: 0 | CE17: 0 | CF17: 0 | CG17: 0 | CH17: 0 | CI17: 0 | CJ17: 0 | CK17: 0 | CL17: 0 | CM17: 0 | CN17: 0 | CO17: 0 | CP17: 0 | CQ17: 0 | CR17: 0 | CS17: 0 | CT17: 0 | CU17: 0 | CV17: 0
D18: Returns (Individual/Shopify) | E18: Returns | F18: Inventory | N18: =SUMIF($O$8:$AV$8,">="&'CURRENT FORECAST START DATE'!$C$4,'Weekly Spend'!O18:AV18) -> 0 | O18: 0 | P18: 0 | Q18: 0 | R18: 0 | S18: 0 | T18: 0 | U18: =238.98+385.68 -> 624.66 | V18: 141.53 | W18: 0 | X18: 0 | Y18: 0 | Z18: 0 | AA18: 0 | AB18: 0 | AC18: 0 | AD18: 0 | AE18: 0 | AF18: 0 | AG18: 0 | AH18: 0 | AI18: 0 | AJ18: 0 | AK18: 0 | AL18: 0 | AM18: 0 | AN18: 0 | AO18: 0 | AP18: 0 | AQ18: 0 | AR18: 0 | AS18: 0 | AT18: 0 | AU18: 0 | AV18: 0 | AW18: 0 | AX18: 0 | AY18: 0 | AZ18: 0 | BA18: 0 | BB18: 0 | BC18: 0 | BD18: 0 | BE18: 0 | BF18: 0 | BG18: 0 | BH18: 0 | BI18: 0 | BJ18: 0 | BK18: 0 | BL18: 0 | BM18: 0 | BN18: 0 | BO18: 0 | BP18: 0 | BQ18: 0 | BR18: 0 | BS18: 0 | BT18: 0 | BU18: 0 | BV18: 0 | BW18: 0 | BX18: 0 | BY18: 0 | BZ18: 0 | CA18: 0 | CB18: 0 | CC18: 0 | CD18: 0 | CE18: 0 | CF18: 0 | CG18: 0 | CH18: 0 | CI18: 0 | CJ18: 0 | CK18: 0 | CL18: 0 | CM18: 0 | CN18: 0 | CO18: 0 | CP18: 0 | CQ18: 0 | CR18: 0 | CS18: 0 | CT18: 0 | CU18: 0 | CV18: 0
A19: ST Cash File (Manual) | B19: =_xlfn.SINGLE(_xlfn.XLOOKUP(F19, $F$87:$F$95, $E$87:$E$95)) -> 6 | C19: K37 | D19: MTN PD | E19: Q15 | F19: Inventory | G19: 71119 | N19: =SUMIF($O$8:$AV$8,">="&'CURRENT FORECAST START DATE'!$C$4,'Weekly Spend'!O19:AV19) -> 45000 | O19: 96000 | P19: 0 | Q19: 0 | R19: 0 | S19: 0 | T19: 0 | U19: 0 | V19: 0 | W19: 0 | X19: 50000 | Z19: 0 | AA19: 0 | AB19: 0 | AC19: 0 | AD19: 0 | AE19: 0 | AF19: 0 | AG19: 0 | AH19: 23100 | AI19: =241500-23100 -> 218400 | AJ19: 0 | AK19: 0 | AL19: 5000 | AM19: 0 | AN19: 0 | AO19: 20000 | AP19: 0 | AQ19: 0 | AR19: 0 | AS19: 0 | AT19: 0 | AU19: 0 | AV19: 25000 | AW19: 0 | AX19: 0 | AY19: 0 | AZ19: 0 | BA19: 0 | BB19: 0 | BC19: 0 | BD19: 0 | BE19: 0 | BF19: 400000 | BG19: 0 | BH19: 0 | BI19: 0 | BJ19: 0 | BK19: 0 | BL19: 0 | BM19: 0 | BN19: 0 | BO19: 0 | BP19: 0 | BQ19: 0 | BR19: 0 | BS19: 0 | BT19: 0 | BU19: 0 | BV19: 0 | BW19: 0 | BX19: 0 | BY19: 0 | BZ19: 0 | CA19: 0 | CB19: 0 | CC19: 0 | CD19: 0 | CE19: 0 | CF19: 0 | CG19: 0 | CH19: 0 | CI19: 0 | CJ19: 0 | CK19: 0 | CL19: 0 | CM19: 0 | CN19: 0 | CO19: 0 | CP19: 0 | CQ19: 0 | CR19: 0 | CS19: 0 | CT19: 0 | CU19: 0 | CV19: 0
D20: CBN | E20: Q12 ROW | F20: Inventory | N20: =SUMIF($O$8:$AV$8,">="&'CURRENT FORECAST START DATE'!$C$4,'Weekly Spend'!O20:AV20) -> 405000 | O20: 0 | P20: 0 | Q20: 0 | R20: 0 | S20: 0 | T20: 0 | U20: 0 | V20: 0 | W20: 0 | X20: 0 | Y20: 0 | Z20: 0 | AA20: 0 | AB20: 0 | AC20: 0 | AD20: 0 | AE20: 0 | AF20: 0 | AG20: 0 | AH20: 0 | AI20: 0 | AJ20: 0 | AK20: 0 | AL20: 0 | AM20: 0 | AN20: 0 | AO20: 0 | AP20: 0 | AQ20: 0 | AR20: 0 | AS20: 0 | AT20: 0 | AU20: 0 | AV20: =25% * (27 * 60000) -> 405000 | AW20: 0 | AX20: 0 | AY20: 0 | BA20: 0 | BB20: 0 | BC20: 0 | BD20: 0 | BE20: 0 | BF20: 0 | BG20: 0 | BH20: 0 | BI20: 0 | BJ20: 0 | BK20: 0 | BL20: 0 | BM20: 0 | BN20: 0 | BO20: 0 | BP20: 0 | BQ20: 0 | BS20: 0 | BT20: 0 | BU20: 0 | BV20: 0 | BW20: 0 | BX20: 0 | BY20: 0 | BZ20: 0 | CA20: 0 | CB20: 0 | CC20: 0 | CD20: 0 | CE20: 0 | CF20: 0 | CG20: 0 | CH20: 0 | CI20: 0 | CJ20: 0 | CK20: 0 | CL20: 0 | CM20: 0 | CN20: 0 | CO20: 0 | CP20: 0 | CQ20: 0 | CR20: 0 | CS20: 0 | CT20: 0 | CU20: 0 | CV20: 0
D21: MTN | E21: Q15 RoW | F21: Inventory | N21: =SUMIF($O$8:$AV$8,">="&'CURRENT FORECAST START DATE'!$C$4,'Weekly Spend'!O21:AV21) -> 174000 | O21: 0 | P21: 0 | Q21: 0 | R21: 0 | S21: 0 | T21: 0 | U21: 0 | V21: 0 | W21: 0 | X21: 0 | AA21: 104700 | AB21: 0 | AC21: 0 | AD21: 0 | AE21: 0 | AF21: 0 | AG21: 0 | AH21: 0 | AI21: 244300 | AJ21: 0 | AK21: 0 | AL21: 0 | AM21: 0 | AN21: 0 | AO21: 0 | AP21: 0 | AQ21: 0 | AR21: =5000*34.8 -> 174000 | AS21: 0 | AT21: 0 | AU21: 0 | AV21: 0 | AW21: 0 | AX21: 0 | AY21: 0 | AZ21: 0 | BA21: 0 | BB21: 0 | BC21: 0 | BD21: 0 | BE21: 0 | BF21: 0 | BG21: 0 | BH21: 0 | BI21: 0 | BJ21: 0 | BK21: 0 | BL21: 0 | BM21: 0 | BN21: 0 | BO21: 0 | BP21: 0 | BQ21: 0 | BR21: 0 | BS21: 0 | BT21: 0 | BU21: 0 | BV21: 0 | BW21: 0 | BX21: 0 | BY21: 0 | BZ21: 0 | CA21: 0 | CB21: 0 | CC21: 0 | CD21: 0 | CE21: 0 | CF21: 0 | CG21: 0 | CH21: 0 | CI21: 0 | CJ21: 0 | CK21: 0 | CL21: 0 | CM21: 0 | CN21: 0 | CO21: 0 | CP21: 0 | CQ21: 0 | CR21: 0 | CS21: 0 | CT21: 0 | CU21: 0 | CV21: 0
A22: Manual Estimate | B22: =_xlfn.SINGLE(_xlfn.XLOOKUP(F22, $F$87:$F$95, $E$87:$E$95)) -> 6 | C22: K47 | D22: CBP | E22: Tariffs | F22: Inventory | M22: 21000 | N22: =SUMIF($O$8:$AV$8,">="&'CURRENT FORECAST START DATE'!$C$4,'Weekly Spend'!O22:AV22) -> 2000 | O22: 0 | P22: 0 | Q22: 0 | R22: 0 | S22: 0 | T22: 0 | U22: 0 | V22: 0 | W22: 0 | X22: 0 | Y22: 0 | Z22: 0 | AA22: =1076.11+48.88 -> 1124.99 | AB22: 0 | AC22: 0 | AD22: 0 | AF22: 2000 | AK22: 2000 | AL22: 0 | AM22: 0 | AN22: 0 | AO22: 0 | AP22: 0 | AQ22: =200*10 -> 2000 | AR22: 0 | AT22: 0 | AV22: 0 | AW22: 0 | AX22: 31194 | AY22: 14400 | AZ22: 0 | BA22: 0 | BB22: 0 | BC22: 0 | BD22: 0 | BE22: 0 | BF22: 60200 | BG22: 0 | BH22: 0 | BI22: 33600 | BJ22: 72786 | BK22: 0 | BL22: 0 | BM22: 0 | BN22: 0 | BO22: 0 | BP22: 0 | BQ22: 0 | BR22: 0 | BS22: 0 | BT22: 0 | BU22: 0 | BV22: 0 | BW22: 0 | BX22: 0 | BY22: 0 | BZ22: 0 | CA22: 0 | CB22: 0 | CC22: 0 | CD22: 0 | CE22: 0 | CF22: 0 | CG22: 0 | CH22: 0 | CI22: 0 | CJ22: 0 | CK22: 0 | CL22: 0 | CM22: 0 | CN22: 0 | CO22: 0 | CP22: 0 | CQ22: 0 | CR22: 0 | CS22: 0 | CT22: 0 | CU22: 0 | CV22: 0
A23: ST Cash File (Manual) | B23: =_xlfn.SINGLE(_xlfn.XLOOKUP(F23, $F$87:$F$95, $E$87:$E$95)) -> 6 | C23: K48 | D23: OL-USA | E23: Shipping | F23: Inventory | M23: 5000 | N23: =SUMIF($O$8:$AV$8,">="&'CURRENT FORECAST START DATE'!$C$4,'Weekly Spend'!O23:AV23) -> 29578 | O23: 0 | P23: 0 | Q23: 0 | R23: 0 | S23: 0 | T23: 0 | U23: 100 | V23: 0 | W23: 0 | X23: 0 | Y23: 19000 | AB23: 21000 | AC23: 0 | AD23: 0 | AE23: =2464+10000+9600 -> 22064 | AF23: 0 | AG23: 15000 | AH23: 0 | AJ23: 8000 | AL23: 15000 | AM23: 0 | AN23: 0 | AO23: 10378 | AP23: 0 | AR23: 0 | AS23: 0 | AT23: 0 | AU23: =4800*4 -> 19200 | AV23: 0 | AW23: 0 | AX23: 0 | AY23: 0 | AZ23: 15000 | BA23: 0 | BB23: 0 | BC23: 0 | BD23: 0 | BE23: 0 | BF23: 0 | BG23: 0 | BH23: 0 | BI23: 0 | BJ23: 30000 | BK23: 0 | BL23: 0 | BM23: 0 | BN23: 0 | BO23: 0 | BP23: 0 | BQ23: 0 | BR23: 0 | BS23: 0 | BT23: 0 | BU23: 0 | BV23: 0 | BW23: 0 | BX23: 0 | BY23: 0 | BZ23: 0 | CA23: 0 | CB23: 0 | CC23: 0 | CD23: 0 | CE23: 0 | CF23: 0 | CG23: 0 | CH23: 0 | CI23: 0 | CJ23: 0 | CK23: 0 | CL23: 0 | CM23: 0 | CN23: 0 | CO23: 0 | CP23: 0 | CQ23: 0 | CR23: 0 | CS23: 0 | CT23: 0 | CU23: 0 | CV23: 0
D24: Gryphon | E24: Contract | F24: Inventory | N24: =SUMIF($O$8:$AV$8,">="&'CURRENT FORECAST START DATE'!$C$4,'Weekly Spend'!O24:AV24) -> 0 | O24: 0 | P24: 0 | Q24: 0 | R24: 0 | S24: 0 | T24: 0 | U24: 0 | V24: 0 | W24: 0 | X24: =2059.5+4907 -> 6966.5 | Y24: 0 | Z24: 0 | AA24: 4555 | AB24: 0 | AC24: 0 | AD24: 0 | AE24: 0 | AF24: 0 | AG24: 0 | AH24: 0 | AI24: 0 | AJ24: 0 | AK24: 0 | AL24: 0 | AM24: 0 | AN24: 0 | AO24: 0 | AP24: 0 | AQ24: 0 | AR24: 0 | AS24: 0 | AT24: 0 | AU24: 0 | AV24: 0 | AW24: 0 | AX24: 0 | AY24: 0 | AZ24: 0 | BA24: 0 | BB24: 0 | BC24: 0 | BD24: 0 | BE24: 0 | BF24: 0 | BG24: 0 | BH24: 0 | BI24: 0 | BJ24: 0 | BK24: 0 | BL24: 0 | BM24: 0 | BN24: 0 | BO24: 0 | BP24: 0 | BQ24: 0 | BR24: 0 | BS24: 0 | BT24: 0 | BU24: 0 | BV24: 0 | BW24: 0 | BX24: 0 | BY24: 0 | BZ24: 0 | CA24: 0 | CB24: 0 | CC24: 0 | CD24: 0 | CE24: 0 | CF24: 0 | CG24: 0 | CH24: 0 | CI24: 0 | CJ24: 0 | CK24: 0 | CL24: 0 | CM24: 0 | CN24: 0 | CO24: 0 | CP24: 0 | CQ24: 0 | CR24: 0 | CS24: 0 | CT24: 0 | CU24: 0 | CV24: 0
D25: Askey | E25: Q20 | F25: NRE | N25: =SUMIF($O$8:$AV$8,">="&'CURRENT FORECAST START DATE'!$C$4,'Weekly Spend'!O25:AV25) -> 0 | O25: 0 | P25: 0 | Q25: 0 | R25: 0 | S25: 0 | T25: 0 | U25: 0 | V25: 0 | W25: 0 | X25: 0 | Y25: 0 | Z25: 0 | AA25: 0 | AB25: 0 | AC25: 0 | AD25: 0 | AE25: 0 | AF25: 0 | AG25: 0 | AH25: 0 | AI25: 0 | AJ25: 0 | AK25: 0 | AL25: 0 | AM25: 0 | AN25: 0 | AO25: 0 | AP25: 0 | AQ25: 0 | AR25: 0 | AS25: 0 | AT25: 0 | AU25: 0 | AV25: 0 | AW25: 0 | AX25: 0 | AY25: 0 | AZ25: 0 | BA25: 0 | BB25: 0 | BC25: 0 | BD25: 0 | BE25: 0 | BF25: 0 | BG25: 0 | BH25: 0 | BI25: 0 | BJ25: 0 | BK25: 0 | BL25: 0 | BM25: 0 | BN25: 0 | BO25: 0 | BP25: 0 | BQ25: 0 | BR25: 0 | BS25: 0 | BT25: 0 | BU25: 0 | BV25: 0 | BW25: 0 | BX25: 0 | BY25: 0 | BZ25: 0 | CA25: 0 | CB25: 0 | CC25: 0 | CD25: 0 | CE25: 0 | CF25: 0 | CG25: 0 | CH25: 0 | CI25: 0 | CJ25: 0 | CK25: 0 | CL25: 0 | CM25: 0 | CN25: 0 | CO25: 0 | CP25: 0 | CQ25: 0 | CR25: 0 | CS25: 0 | CT25: 0 | CU25: 0 | CV25: 0
D26: Atel | E26: P15 NRE | F26: NRE | N26: =SUMIF($O$8:$AV$8,">="&'CURRENT FORECAST START DATE'!$C$4,'Weekly Spend'!O26:AV26) -> 94250 | O26: 0 | P26: 0 | Q26: 0 | R26: 0 | S26: 0 | T26: 0 | U26: 0 | V26: 0 | W26: 0 | X26: 118750 | Y26: 0 | Z26: 0 | AA26: 0 | AC26: 37500 | AD26: 0 | AE26: 0 | AF26: 0 | AG26: 0 | AH26: 0 | AI26: 0 | AK26: 0 | AL26: 0 | AM26: 0 | AN26: 0 | AQ26: 0 | AR26: 0 | AS26: =37500+25000+13000 -> 75500 | AT26: 18750 | AU26: 0 | AV26: 0 | AW26: 0 | AX26: 38000 | AY26: 0 | AZ26: 0 | BA26: 0 | BB26: 0 | BC26: 0 | BD26: 0 | BE26: 0 | BF26: 0 | BG26: 0 | BH26: 0 | BI26: 0 | BJ26: 0 | BK26: 0 | BL26: 0 | BM26: 0 | BN26: 0 | BO26: 0 | BP26: 0 | BQ26: 0 | BR26: 0 | BS26: 0 | BT26: 0 | BU26: 0 | BV26: 0 | BW26: 0 | BX26: 0 | BY26: 0 | BZ26: 0 | CA26: 0 | CB26: 0 | CC26: 0 | CD26: 0 | CE26: 0 | CF26: 0 | CG26: 0 | CH26: 0 | CI26: 0 | CJ26: 0 | CK26: 0 | CL26: 0 | CM26: 0 | CN26: 0 | CO26: 0 | CP26: 0 | CQ26: 0 | CR26: 0 | CS26: 0 | CT26: 0 | CU26: 0 | CV26: 0
D27: Atel | E27: P15RoW | F27: NRE | N27: =SUMIF($O$8:$AV$8,">="&'CURRENT FORECAST START DATE'!$C$4,'Weekly Spend'!O27:AV27) -> 0 | O27: 0 | P27: 0 | Q27: 0 | R27: 0 | S27: 0 | T27: 0 | U27: 0 | V27: 0 | W27: 0 | X27: 0 | Y27: 0 | Z27: 0 | AA27: 0 | AB27: 0 | AC27: 0 | AD27: 0 | AE27: 0 | AF27: 0 | AG27: 0 | AH27: 0 | AI27: 0 | AJ27: 0 | AK27: 0 | AL27: 0 | AM27: 0 | AN27: 0 | AO27: 0 | AP27: 0 | AQ27: 0 | AR27: 0 | AS27: 0 | AT27: 0 | AU27: 0 | AV27: 0 | AW27: 0 | AX27: 0 | AY27: 0 | AZ27: 0 | BA27: 0 | BB27: 0 | BC27: 0 | BD27: 0 | BE27: 0 | BF27: 0 | BG27: 0 | BH27: 0 | BI27: 0 | BJ27: 0 | BK27: 0 | BL27: 0 | BM27: 0 | BN27: 0 | BO27: 0 | BP27: 0 | BQ27: 0 | BR27: 0 | BS27: 0 | BT27: 0 | BU27: 0 | BV27: 0 | BW27: 0 | BX27: 0 | BY27: 0 | BZ27: 0 | CA27: 0 | CB27: 0 | CC27: 0 | CD27: 0 | CE27: 0 | CF27: 0 | CG27: 0 | CH27: 0 | CI27: 0 | CJ27: 0 | CK27: 0 | CL27: 0 | CM27: 0 | CN27: 0 | CO27: 0 | CP27: 0 | CQ27: 0 | CR27: 0 | CS27: 0 | CT27: 0 | CU27: 0 | CV27: 0
D28: CBN | E28: Q12 | F28: NRE | N28: =SUMIF($O$8:$AV$8,">="&'CURRENT FORECAST START DATE'!$C$4,'Weekly Spend'!O28:AV28) -> 155000 | O28: 0 | P28: 0 | Q28: 0 | R28: 0 | S28: 0 | T28: 0 | U28: 0 | V28: 0 | W28: 0 | X28: 0 | Y28: 0 | Z28: 0 | AB28: 0 | AC28: 0 | AD28: 0 | AF28: 0 | AG28: 0 | AH28: 0 | AI28: 0 | AJ28: 0 | AK28: 0 | AL28: 0 | AM28: 0 | AN28: 0 | AO28: 0 | AQ28: 155000 | AR28: 0 | AS28: 0 | AT28: 0 | AU28: 0 | AW28: 0 | AX28: 0 | AY28: 0 | AZ28: 0 | BA28: 0 | BB28: 0 | BC28: 50000 | BD28: 0 | BE28: 155000 | BF28: 0 | BG28: 0 | BH28: 45000 | BI28: 0 | BJ28: 0 | BK28: 0 | BL28: 0 | BM28: 0 | BN28: 0 | BO28: 0 | BP28: 0 | BQ28: 0 | BR28: 0 | BS28: 0 | BT28: 0 | BU28: 0 | BV28: 0 | BW28: 0 | BX28: 0 | BY28: 0 | BZ28: 0 | CA28: 0 | CB28: 0 | CC28: 0 | CD28: 0 | CE28: 0 | CF28: 0 | CG28: 0 | CH28: 0 | CI28: 0 | CJ28: 0 | CK28: 0 | CL28: 0 | CM28: 0 | CN28: 0 | CO28: 0 | CP28: 0 | CQ28: 0 | CR28: 0 | CS28: 0 | CT28: 0 | CU28: 0 | CV28: 0
D29: CBN | E29: Q12 ROW | F29: NRE | N29: =SUMIF($O$8:$AV$8,">="&'CURRENT FORECAST START DATE'!$C$4,'Weekly Spend'!O29:AV29) -> 0 | O29: 0 | P29: 0 | Q29: 0 | R29: 0 | S29: 0 | T29: 0 | U29: 0 | V29: 0 | W29: 0 | X29: 0 | Y29: 0 | Z29: 0 | AB29: 0 | AC29: 0 | AD29: 0 | AE29: 0 | AF29: 0 | AH29: 0 | AL29: 0 | AM29: 0 | AN29: 0 | AP29: 0 | AQ29: 0 | AR29: 0 | AS29: 0 | AT29: 0 | AU29: 0 | AV29: 0 | AW29: 0 | AX29: 0 | AY29: 0 | AZ29: 0 | BA29: 0 | BB29: 0 | BC29: 0 | BD29: 0 | BE29: 0 | BF29: 0 | BG29: 0 | BH29: 0 | BI29: 0 | BJ29: 0 | BK29: 0 | BL29: 0 | BM29: 0 | BN29: 0 | BO29: 0 | BP29: 0 | BQ29: 0 | BR29: 0 | BS29: 0 | BT29: 0 | BU29: 0 | BV29: 0 | BW29: 0 | BX29: 0 | BY29: 0 | BZ29: 0 | CA29: 0 | CB29: 0 | CC29: 0 | CD29: 0 | CE29: 0 | CF29: 0 | CG29: 0 | CH29: 0 | CI29: 0 | CJ29: 0 | CK29: 0 | CL29: 0 | CM29: 0 | CN29: 0 | CO29: 0 | CP29: 0 | CQ29: 0 | CR29: 0 | CS29: 0 | CT29: 0 | CU29: 0 | CV29: 0
D30: MTN MMA | E30: Q15 | F30: NRE | G30: 71119 | N30: =SUMIF($O$8:$AV$8,">="&'CURRENT FORECAST START DATE'!$C$4,'Weekly Spend'!O30:AU30) -> 0 | O30: 0 | P30: 0 | Q30: 0 | R30: 0 | S30: 0 | T30: 0 | U30: 0 | V30: 0 | W30: 0 | X30: 0 | Y30: 0 | Z30: 0 | AA30: 0 | AC30: 0 | AD30: 0 | AE30: 0 | AG30: 0 | AH30: =71119+6350 -> 77469 | AK30: 0 | AL30: 0 | AM30: 0 | AN30: 0 | AO30: 0 | AP30: 0 | AQ30: 0 | AR30: 0 | AS30: 0 | AT30: 0 | AU30: 0 | AV30: 0 | AW30: 0 | AX30: 0 | AY30: 0 | AZ30: 0 | BA30: 0 | BB30: 0 | BC30: 0 | BD30: 0 | BE30: 0 | BF30: 0 | BG30: 0 | BH30: 0 | BI30: 0 | BJ30: 0 | BK30: 0 | BL30: 0 | BM30: 0 | BN30: 0 | BO30: 0 | BP30: 0 | BQ30: 0 | BR30: 0 | BS30: 0 | BT30: 0 | BU30: 0 | BV30: 0 | BW30: 0 | BX30: 0 | BY30: 0 | BZ30: 0 | CA30: 0 | CB30: 0 | CC30: 0 | CD30: 0 | CE30: 0 | CF30: 0 | CG30: 0 | CH30: 0 | CI30: 0 | CJ30: 0 | CK30: 0 | CL30: 0 | CM30: 0 | CN30: 0 | CO30: 0 | CP30: 0 | CQ30: 0 | CR30: 0 | CS30: 0 | CT30: 0 | CU30: 0 | CV30: 0
D31: Compal | E31: B15 RoW | F31: NRE | N31: =SUMIF($O$8:$AV$8,">="&'CURRENT FORECAST START DATE'!$C$4,'Weekly Spend'!O31:AV31) -> 0 | O31: 0 | P31: 0 | Q31: 0 | R31: 0 | S31: 0 | T31: 0 | U31: 0 | V31: 0 | W31: 0 | Z31: 0 | AC31: 0 | AE31: 0 | AF31: 0 | AG31: 0 | AI31: 0 | AK31: 0 | AL31: 0 | AT31: 0 | AU31: 0 | AV31: 0 | AW31: 0 | AX31: 0 | AY31: 0 | AZ31: 0 | BA31: 0 | BB31: 0 | BC31: 0 | BD31: 0 | BE31: 0 | BF31: 0 | BG31: 0 | BH31: 0 | BI31: 0 | BJ31: 0 | BK31: 0 | BL31: 0 | BM31: 0 | BN31: 0 | BO31: 0 | BP31: 0 | BQ31: 0 | BR31: 0 | BS31: 0 | BT31: 0 | BU31: 0 | BV31: 0 | BW31: 0 | BX31: 0 | BY31: 0 | BZ31: 0 | CA31: 0 | CB31: 0 | CC31: 0 | CD31: 0 | CE31: 0 | CF31: 0 | CG31: 0 | CH31: 0 | CI31: 0 | CJ31: 0 | CK31: 0 | CL31: 0 | CM31: 0 | CN31: 0 | CO31: 0 | CP31: 0 | CQ31: 0 | CR31: 0 | CS31: 0 | CT31: 0 | CU31: 0 | CV31: 0
A32: ST Cash File (Manual) | B32: =_xlfn.SINGLE(_xlfn.XLOOKUP(F32, $F$87:$F$95, $E$87:$E$95)) -> 8 | C32: K33 | D32: Compal | E32: B15 | F32: NRE | I32: 151355 | L32: 33000 | N32: =SUMIF($O$8:$AV$8,">="&'CURRENT FORECAST START DATE'!$C$4,'Weekly Spend'!O32:AV32) -> 28500 | O32: 0 | P32: 0 | Q32: 0 | R32: 0 | S32: 0 | T32: 0 | U32: 0 | V32: 0 | W32: 0 | X32: 5292 | Y32: 0 | AA32: 0 | AB32: 0 | AC32: 0 | AD32: 5292 | AE32: 0 | AF32: 0 | AH32: 0 | AI32: 0 | AJ32: 0 | AM32: 0 | AN32: 0 | AO32: 0 | AP32: 0 | AQ32: 0 | AR32: 0 | AS32: 28500 | AT32: 0 | AU32: 0 | AV32: 0 | AW32: 0 | AX32: 0 | AY32: 0 | AZ32: 0 | BA32: 0 | BB32: 0 | BC32: 0 | BD32: 0 | BE32: 0 | BF32: 0 | BG32: 0 | BH32: 0 | BI32: 0 | BJ32: 0 | BK32: 0 | BL32: 0 | BM32: 0 | BN32: 0 | BO32: 0 | BP32: 0 | BQ32: 0 | BR32: 0 | BS32: 0 | BT32: 0 | BU32: 0 | BV32: 0 | BW32: 0 | BX32: 0 | BY32: 0 | BZ32: 0 | CA32: 0 | CB32: 0 | CC32: 0 | CD32: 0 | CE32: 0 | CF32: 0 | CG32: 0 | CH32: 0 | CI32: 0 | CJ32: 0 | CK32: 0 | CL32: 0 | CM32: 0 | CN32: 0 | CO32: 0 | CP32: 0 | CQ32: 0 | CR32: 0 | CS32: 0 | CT32: 0 | CU32: 0 | CV32: 0
D33: Atel | E33: Motosync+ | F33: NRE | N33: =SUMIF($O$8:$AV$8,">="&'CURRENT FORECAST START DATE'!$C$4,'Weekly Spend'!O33:AV33) -> 12500 | O33: 0 | P33: 0 | Q33: 0 | R33: 0 | S33: 0 | T33: 0 | U33: 0 | V33: 0 | W33: 0 | Z33: 0 | AB33: 0 | AF33: 0 | AG33: 0 | AH33: 0 | AI33: 0 | AJ33: 0 | AK33: 0 | AL33: 0 | AO33: 0 | AP33: 0 | AQ33: 0 | AR33: 0 | AS33: 0 | AT33: 0 | AU33: 12500 | AV33: 0 | AW33: 0 | AX33: 0 | AY33: 0 | AZ33: 0 | BA33: 0 | BB33: 0 | BC33: 0 | BD33: 0 | BE33: 0 | BF33: 0 | BG33: 0 | BH33: 0 | BI33: 0 | BJ33: 0 | BK33: 0 | BL33: 0 | BM33: 0 | BN33: 0 | BO33: 0 | BP33: 0 | BQ33: 0 | BR33: 0 | BS33: 0 | BT33: 0 | BU33: 0 | BV33: 0 | BW33: 0 | BX33: 0 | BY33: 0 | BZ33: 0 | CA33: 0 | CB33: 0 | CC33: 0 | CD33: 0 | CE33: 0 | CF33: 0 | CG33: 0 | CH33: 0 | CI33: 0 | CJ33: 0 | CK33: 0 | CL33: 0 | CM33: 0 | CN33: 0 | CO33: 0 | CP33: 0 | CQ33: 0 | CR33: 0 | CS33: 0 | CT33: 0 | CU33: 0 | CV33: 0
D34: MTN | E34: Q15 RoW | F34: NRE | N34: =SUMIF($O$8:$AV$8,">="&'CURRENT FORECAST START DATE'!$C$4,'Weekly Spend'!O34:AV34) -> 25196.66 | O34: 0 | P34: 0 | Q34: 0 | R34: 0 | S34: 0 | T34: 0 | U34: 0 | V34: 0 | W34: 0 | X34: 21053 | Z34: 0 | AA34: 0 | AB34: 0 | AC34: 0 | AD34: 0 | AE34: 0 | AF34: 0 | AG34: 0 | AH34: 0 | AI34: 21053 | AJ34: 0 | AK34: 0 | AM34: 0 | AN34: 0 | AO34: 0 | AP34: 0 | AQ34: 0 | AR34: 0 | AS34: 25196.66 | AT34: 0 | AU34: 0 | AV34: 0 | AW34: 0 | AX34: 0 | AY34: 0 | AZ34: 0 | BA34: 0 | BB34: 0 | BC34: 0 | BD34: 0 | BE34: 0 | BF34: 0 | BG34: 0 | BH34: 0 | BI34: 0 | BJ34: 0 | BK34: 0 | BL34: 0 | BM34: 0 | BN34: 0 | BO34: 0 | BP34: 0 | BQ34: 0 | BR34: 0 | BS34: 0 | BT34: 0 | BU34: 0 | BV34: 0 | BW34: 0 | BX34: 0 | BY34: 0 | BZ34: 0 | CA34: 0 | CB34: 0 | CC34: 0 | CD34: 0 | CE34: 0 | CF34: 0 | CG34: 0 | CH34: 0 | CI34: 0 | CJ34: 0 | CK34: 0 | CL34: 0 | CM34: 0 | CN34: 0 | CO34: 0 | CP34: 0 | CQ34: 0 | CR34: 0 | CS34: 0 | CT34: 0 | CU34: 0 | CV34: 0
D35: Gryphon | E35: P15 | F35: NRE | N35: =SUMIF($O$8:$AV$8,">="&'CURRENT FORECAST START DATE'!$C$4,'Weekly Spend'!O35:AV35) -> 58000 | AG35: 4846.15 | AJ35: 3000 | AN35: 3000 | AO35: 3000 | AP35: 0 | AQ35: 0 | AR35: 0 | AU35: 55000 | AW35: 50000 | AY35: 50000 | BG35: 0 | BH35: 0 | BI35: 0 | BJ35: 0 | BK35: 0 | BL35: 0 | BM35: 0 | BN35: 0 | BO35: 0 | BP35: 0 | BQ35: 0 | BR35: 35000 | BS35: 0 | BT35: 35000
D36: Gryphon | E36: Q15 | F36: NRE | N36: =SUMIF($O$8:$AV$8,">="&'CURRENT FORECAST START DATE'!$C$4,'Weekly Spend'!O36:AV36) -> 96307.69 | AJ36: 6000 | AN36: 12000 | AO36: 41307.69 | AP36: 0 | AQ36: 0 | AR36: 0 | AS36: 55000 | BG36: 0 | BH36: 0 | BI36: 0 | BJ36: 0 | BK36: 0 | BL36: 0 | BM36: 0 | BN36: 0 | BO36: 0 | BP36: 0 | BQ36: 0 | BR36: 0 | BS36: 0 | BT36: 0
D37: Gryphon | E37: Q12 | F37: NRE | N37: =SUMIF($O$8:$AV$8,">="&'CURRENT FORECAST START DATE'!$C$4,'Weekly Spend'!O37:AV37) -> 0 | AP37: 0 | AQ37: 0 | AR37: 0 | BN37: 35000
A38: SC File (Link) | B38: =_xlfn.SINGLE(_xlfn.XLOOKUP(F38, $F$87:$F$95, $E$87:$E$95)) -> 8 | C38: K4 | D38: Gryphon | E38: Contract/Weekly | F38: NRE | G38: {=INDEX('SC Cost File'!$A$2:$AB$31,MATCH($C38,'SC Cost File'!$A$2:$A$31,0),MATCH(G$7,'SC Cost File'!$A$2:$AB$2,0))/COUNTIF($G$7:$CV$7,G$7)} -> 15000 | H38: {=INDEX('SC Cost File'!$A$2:$AB$31,MATCH($C38,'SC Cost File'!$A$2:$A$31,0),MATCH(H$7,'SC Cost File'!$A$2:$AB$2,0))/COUNTIF($G$7:$CV$7,H$7)} -> 15000 | I38: {=INDEX('SC Cost File'!$A$2:$AB$31,MATCH($C38,'SC Cost File'!$A$2:$A$31,0),MATCH(I$7,'SC Cost File'!$A$2:$AB$2,0))/COUNTIF($G$7:$CV$7,I$7)} -> 7500 | J38: {=INDEX('SC Cost File'!$A$2:$AB$31,MATCH($C38,'SC Cost File'!$A$2:$A$31,0),MATCH(J$7,'SC Cost File'!$A$2:$AB$2,0))/COUNTIF($G$7:$CV$7,J$7)} -> 7500 | K38: {=INDEX('SC Cost File'!$A$2:$AB$31,MATCH($C38,'SC Cost File'!$A$2:$A$31,0),MATCH(K$7,'SC Cost File'!$A$2:$AB$2,0))/COUNTIF($G$7:$CV$7,K$7)} -> 7500 | L38: {=INDEX('SC Cost File'!$A$2:$AB$31,MATCH($C38,'SC Cost File'!$A$2:$A$31,0),MATCH(L$7,'SC Cost File'!$A$2:$AB$2,0))/COUNTIF($G$7:$CV$7,L$7)} -> 7500 | M38: {=INDEX('SC Cost File'!$A$2:$AB$31,MATCH($C38,'SC Cost File'!$A$2:$A$31,0),MATCH(M$7,'SC Cost File'!$A$2:$AB$2,0))/COUNTIF($G$7:$CV$7,M$7)} -> 7500 | N38: =SUMIF($O$8:$AV$8,">="&'CURRENT FORECAST START DATE'!$C$4,'Weekly Spend'!O38:AV38) -> 13384.62 | O38: 0 | P38: 0 | Q38: 0 | R38: 0 | S38: 0 | T38: 0 | U38: 31000 | V38: 0 | W38: 0 | X38: 29769.23 | Y38: 0 | Z38: =34169+162 -> 34331 | AA38: =34615 -> 34615 | AB38: 0 | AC38: 0 | AD38: =34950 -> 34950 | AE38: 0 | AF38: 0 | AG38: =36461.64+3692.31 -> 40153.95 | AI38: 40000 | AJ38: 0 | AK38: 31615.39 | AN38: 35307.69 | AO38: 13384.62 | AP38: 0 | AQ38: 0 | AR38: 0 | AS38: 0 | AT38: 0 | AU38: 0 | AV38: 0 | AW38: 0 | AX38: 0 | AY38: 0 | AZ38: 50000 | BA38: 0 | BB38: 0 | BC38: 50000 | BD38: 0 | BE38: 40000 | BG38: 0 | BH38: 0 | BI38: 35000 | BJ38: 0 | BK38: 0 | BL38: 40250 | BM38: 0 | BN38: 0 | BO38: 0 | BP38: 35000 | BQ38: 0 | BR38: 0 | BS38: 0 | BT38: 0 | BU38: 0 | BV38: 0 | BW38: 0 | BX38: 0 | BY38: 0 | BZ38: 0 | CA38: 0 | CB38: 0 | CC38: 0 | CD38: 0 | CE38: 0 | CF38: 0 | CG38: 0 | CH38: 0 | CI38: 0 | CJ38: 0 | CK38: 0 | CL38: 0 | CM38: 0 | CN38: 0 | CO38: 0 | CP38: 0 | CQ38: 0 | CR38: 0 | CS38: 0 | CT38: 0 | CU38: 0 | CV38: 0
A39: ST Cash File (Manual) | B39: =_xlfn.SINGLE(_xlfn.XLOOKUP(F39, $F$87:$F$95, $E$87:$E$95)) -> 2 | C39: K23 | D39: AWS | E39: Services | F39: OpEx | G39: 0 | H39: 0 | I39: 0 | J39: 0 | K39: 0 | L39: 0 | M39: 40000 | N39: =SUMIF($O$8:$AV$8,">="&'CURRENT FORECAST START DATE'!$C$4,'Weekly Spend'!O39:AV39) -> 40000 | O39: 0 | P39: 0 | Q39: 0 | R39: 40000 | S39: 0 | T39: 0 | U39: 0 | V39: 42853 | W39: 0 | X39: 0 | Y39: 0 | Z39: 42000 | AA39: 0 | AB39: 0 | AC39: 0 | AE39: 42000 | AF39: 0 | AG39: 0 | AI39: 0 | AJ39: 43500 | AK39: 0 | AM39: 0 | AN39: 40000 | AO39: 0 | AR39: 40000 | AS39: 0 | AU39: 0 | AW39: 40000 | AY39: 0 | BA39: 40000 | BC39: 0 | BE39: 40000 | BG39: 0 | BH39: 0 | BJ39: 40000 | BK39: 0 | BL39: 0 | BN39: 40000 | BO39: 0 | BP39: 0 | BR39: 40000 | BS39: 0 | BT39: 0 | BU39: 0 | CB39: 0 | CF39: 0 | CJ39: 0 | CO39: 0 | CQ39: 0 | CS39: 0 | CU39: 0
A40: ST Cash File (Manual) | B40: =_xlfn.SINGLE(_xlfn.XLOOKUP(F40, $F$87:$F$95, $E$87:$E$95)) -> 2 | C40: K39 | D40: CATV (Triage, Refurb, RMA) | E40: Services | F40: OpEx | M40: 50000 | N40: =SUMIF($O$8:$AV$8,">="&'CURRENT FORECAST START DATE'!$C$4,'Weekly Spend'!O40:AV40) -> 22572.5 | O40: 0 | P40: 0 | Q40: 3500 | R40: 0 | S40: 0 | T40: 0 | U40: 0 | V40: 0 | W40: 0 | X40: =1040+143 -> 1183 | Y40: =4030+65 -> 4095 | Z40: 2249 | AD40: 15704 | AE40: =250+3999.91 -> 4249.91 | AF40: 12493 | AG40: =1573 -> 1573 | AH40: =1495+2834+1521+10000 -> 15850 | AI40: 4000 | AJ40: 3484 | AK40: =1963+195 -> 2158 | AL40: 7000 | AM40: =338+2327+429 -> 3094 | AN40: =4797+767+17797 -> 23361 | AQ40: =1485+1087.5 -> 2572.5 | AR40: =3000+1000 -> 4000 | AS40: =3000+1000 -> 4000 | AT40: =3000+1000 -> 4000 | AU40: =3000+1000 -> 4000 | AV40: =3000+1000 -> 4000 | AW40: =3000+1000 -> 4000 | AX40: =3000+1000 -> 4000 | AY40: =3000+1000 -> 4000 | ... BL40: =3000+1000 -> 4000 | BO40: =3000+1000 -> 4000 | BP40: =3000+1000 -> 4000 | BQ40: =3000+1000 -> 4000 | BR40: =3000+1000 -> 4000 | BS40: =3000+1000 -> 4000 | BT40: =3000+1000 -> 4000 | BU40: =3000+1000 -> 4000 | BV40: =3000+1000 -> 4000 | ... CV40: =3000+1000 -> 4000
A41: Manual Invoice | B41: =_xlfn.SINGLE(_xlfn.XLOOKUP(F41, $F$87:$F$95, $E$87:$E$95)) -> 2 | C41: K46 | D41: Tide Rock | E41: Allocation | F41: OpEx | I41: 24152.95 | M41: =I41 -> 24152.95 | N41: =SUMIF($O$8:$AV$8,">="&'CURRENT FORECAST START DATE'!$C$4,'Weekly Spend'!O41:AV41) -> 44000 | O41: 0 | P41: 0 | Q41: 0 | R41: =I41 -> 24152.95 | S41: 0 | T41: 0 | U41: 0 | V41: 0 | W41: 0 | X41: 0 | Y41: 0 | Z41: =9300+15598 -> 24898 | AA41: 0 | AB41: 0 | AC41: 0 | AE41: 20000 | AF41: 0 | AG41: 0 | AH41: 0 | AI41: =AD41 -> 0 | AJ41: 0 | AK41: 0 | AL41: 0 | AM41: =AI41 -> 0 | AN41: 0 | AO41: 0 | AP41: 0 | AR41: 22000 | AS41: 0 | AT41: 0 | AU41: 0 | AV41: 22000 | AW41: 0 | AX41: 0 | AY41: 0 | AZ41: 22000 | BA41: 0 | BB41: 0 | BC41: 0 | BD41: 22000 | BE41: 0 | BF41: 0 | BG41: 0 | BH41: 0 | BI41: 22000 | BJ41: 0 | BK41: 0 | BL41: 0 | BM41: 22000 | BN41: 0 | BO41: 0 | BP41: 0 | BQ41: 22000 | BR41: 0 | BS41: 0 | BT41: 0 | BU41: 0 | BV41: 22000 | BW41: 0 | BX41: 0 | BY41: 0 | BZ41: 22000 | CA41: 0 | CB41: 0 | CC41: 0 | CD41: 0 | CE41: 22000 | CF41: 0 | CG41: 0 | CH41: 0 | CI41: 22000 | CJ41: 0 | CK41: 0 | CL41: 0 | CM41: 22000 | CN41: 0 | CO41: 0 | CP41: 0 | CQ41: 0 | CR41: 22000 | CS41: 0 | CT41: 0 | CU41: 0 | CV41: 22000
A42: SC File (Link) | B42: =_xlfn.SINGLE(_xlfn.XLOOKUP(F42, $F$87:$F$95, $E$87:$E$95)) -> 8 | C42: K29 | D42: CableLabs/Kyrio | E42: Services | F42: NRE | G42: {=INDEX('SC Cost File'!$A$2:$AB$31,MATCH($C42,'SC Cost File'!$A$2:$A$31,0),MATCH(G$7,'SC Cost File'!$A$2:$AB$2,0))/COUNTIF($G$7:$CV$7,G$7)} -> 0 | H42: {=INDEX('SC Cost File'!$A$2:$AB$31,MATCH($C42,'SC Cost File'!$A$2:$A$31,0),MATCH(H$7,'SC Cost File'!$A$2:$AB$2,0))/COUNTIF($G$7:$CV$7,H$7)} -> 0 | I42: {=INDEX('SC Cost File'!$A$2:$AB$31,MATCH($C42,'SC Cost File'!$A$2:$A$31,0),MATCH(I$7,'SC Cost File'!$A$2:$AB$2,0))/COUNTIF($G$7:$CV$7,I$7)} -> 0 | J42: {=INDEX('SC Cost File'!$A$2:$AB$31,MATCH($C42,'SC Cost File'!$A$2:$A$31,0),MATCH(J$7,'SC Cost File'!$A$2:$AB$2,0))/COUNTIF($G$7:$CV$7,J$7)} -> 0 | K42: {=INDEX('SC Cost File'!$A$2:$AB$31,MATCH($C42,'SC Cost File'!$A$2:$A$31,0),MATCH(K$7,'SC Cost File'!$A$2:$AB$2,0))/COUNTIF($G$7:$CV$7,K$7)} -> 0 | L42: {=INDEX('SC Cost File'!$A$2:$AB$31,MATCH($C42,'SC Cost File'!$A$2:$A$31,0),MATCH(L$7,'SC Cost File'!$A$2:$AB$2,0))/COUNTIF($G$7:$CV$7,L$7)} -> 0 | M42: {=INDEX('SC Cost File'!$A$2:$AB$31,MATCH($C42,'SC Cost File'!$A$2:$A$31,0),MATCH(M$7,'SC Cost File'!$A$2:$AB$2,0))/COUNTIF($G$7:$CV$7,M$7)} -> 0 | N42: =SUMIF($O$8:$AV$8,">="&'CURRENT FORECAST START DATE'!$C$4,'Weekly Spend'!O42:AV42) -> 0 | O42: {=INDEX('SC Cost File'!$A$2:$AB$31,MATCH($C42,'SC Cost File'!$A$2:$A$31,0),MATCH(O$7,'SC Cost File'!$A$2:$AB$2,0))/COUNTIF($G$7:$CV$7,O$7)} -> 0 | P42: {=INDEX('SC Cost File'!$A$2:$AB$31,MATCH($C42,'SC Cost File'!$A$2:$A$31,0),MATCH(P$7,'SC Cost File'!$A$2:$AB$2,0))/COUNTIF($G$7:$CV$7,P$7)} -> 0 | Q42: {=INDEX('SC Cost File'!$A$2:$AB$31,MATCH($C42,'SC Cost File'!$A$2:$A$31,0),MATCH(Q$7,'SC Cost File'!$A$2:$AB$2,0))/COUNTIF($G$7:$CV$7,Q$7)} -> 0 | R42: {=INDEX('SC Cost File'!$A$2:$AB$31,MATCH($C42,'SC Cost File'!$A$2:$A$31,0),MATCH(R$7,'SC Cost File'!$A$2:$AB$2,0))/COUNTIF($G$7:$CV$7,R$7)} -> 0 | S42: {=INDEX('SC Cost File'!$A$2:$AB$31,MATCH($C42,'SC Cost File'!$A$2:$A$31,0),MATCH(S$7,'SC Cost File'!$A$2:$AB$2,0))/COUNTIF($G$7:$CV$7,S$7)} -> 0 | T42: {=INDEX('SC Cost File'!$A$2:$AB$31,MATCH($C42,'SC Cost File'!$A$2:$A$31,0),MATCH(T$7,'SC Cost File'!$A$2:$AB$2,0))/COUNTIF($G$7:$CV$7,T$7)} -> 0 | U42: {=INDEX('SC Cost File'!$A$2:$AB$31,MATCH($C42,'SC Cost File'!$A$2:$A$31,0),MATCH(U$7,'SC Cost File'!$A$2:$AB$2,0))/COUNTIF($G$7:$CV$7,U$7)} -> 0 | V42: {=INDEX('SC Cost File'!$A$2:$AB$31,MATCH($C42,'SC Cost File'!$A$2:$A$31,0),MATCH(V$7,'SC Cost File'!$A$2:$AB$2,0))/COUNTIF($G$7:$CV$7,V$7)} -> 0 | ... AD42: {=INDEX('SC Cost File'!$A$2:$AB$31,MATCH($C42,'SC Cost File'!$A$2:$A$31,0),MATCH(AD$7,'SC Cost File'!$A$2:$AB$2,0))/COUNTIF($G$7:$CV$7,AD$7)} -> 0 | AF42: {=INDEX('SC Cost File'!$A$2:$AB$31,MATCH($C42,'SC Cost File'!$A$2:$A$31,0),MATCH(AF$7,'SC Cost File'!$A$2:$AB$2,0))/COUNTIF($G$7:$CV$7,AF$7)} -> 0 | AG42: {=INDEX('SC Cost File'!$A$2:$AB$31,MATCH($C42,'SC Cost File'!$A$2:$A$31,0),MATCH(AG$7,'SC Cost File'!$A$2:$AB$2,0))/COUNTIF($G$7:$CV$7,AG$7)} -> 0 | AH42: {=INDEX('SC Cost File'!$A$2:$AB$31,MATCH($C42,'SC Cost File'!$A$2:$A$31,0),MATCH(AH$7,'SC Cost File'!$A$2:$AB$2,0))/COUNTIF($G$7:$CV$7,AH$7)} -> 0 | AI42: {=INDEX('SC Cost File'!$A$2:$AB$31,MATCH($C42,'SC Cost File'!$A$2:$A$31,0),MATCH(AI$7,'SC Cost File'!$A$2:$AB$2,0))/COUNTIF($G$7:$CV$7,AI$7)} -> 0 | AJ42: {=INDEX('SC Cost File'!$A$2:$AB$31,MATCH($C42,'SC Cost File'!$A$2:$A$31,0),MATCH(AJ$7,'SC Cost File'!$A$2:$AB$2,0))/COUNTIF($G$7:$CV$7,AJ$7)} -> 0 | AM42: {=INDEX('SC Cost File'!$A$2:$AB$31,MATCH($C42,'SC Cost File'!$A$2:$A$31,0),MATCH(AM$7,'SC Cost File'!$A$2:$AB$2,0))/COUNTIF($G$7:$CV$7,AM$7)} -> 0 | AR42: {=INDEX('SC Cost File'!$A$2:$AB$31,MATCH($C42,'SC Cost File'!$A$2:$A$31,0),MATCH(AR$7,'SC Cost File'!$A$2:$AB$2,0))/COUNTIF($G$7:$CV$7,AR$7)} -> 0 | AS42: {=INDEX('SC Cost File'!$A$2:$AB$31,MATCH($C42,'SC Cost File'!$A$2:$A$31,0),MATCH(AS$7,'SC Cost File'!$A$2:$AB$2,0))/COUNTIF($G$7:$CV$7,AS$7)} -> 0 | AT42: {=INDEX('SC Cost File'!$A$2:$AB$31,MATCH($C42,'SC Cost File'!$A$2:$A$31,0),MATCH(AT$7,'SC Cost File'!$A$2:$AB$2,0))/COUNTIF($G$7:$CV$7,AT$7)} -> 0 | AV42: {=INDEX('SC Cost File'!$A$2:$AB$31,MATCH($C42,'SC Cost File'!$A$2:$A$31,0),MATCH(AV$7,'SC Cost File'!$A$2:$AB$2,0))/COUNTIF($G$7:$CV$7,AV$7)} -> 0 | AW42: {=INDEX('SC Cost File'!$A$2:$AB$31,MATCH($C42,'SC Cost File'!$A$2:$A$31,0),MATCH(AW$7,'SC Cost File'!$A$2:$AB$2,0))/COUNTIF($G$7:$CV$7,AW$7)} -> 0 | AX42: {=INDEX('SC Cost File'!$A$2:$AB$31,MATCH($C42,'SC Cost File'!$A$2:$A$31,0),MATCH(AX$7,'SC Cost File'!$A$2:$AB$2,0))/COUNTIF($G$7:$CV$7,AX$7)} -> 0 | AY42: {=INDEX('SC Cost File'!$A$2:$AB$31,MATCH($C42,'SC Cost File'!$A$2:$A$31,0),MATCH(AY$7,'SC Cost File'!$A$2:$AB$2,0))/COUNTIF($G$7:$CV$7,AY$7)} -> 0 | AZ42: {=INDEX('SC Cost File'!$A$2:$AB$31,MATCH($C42,'SC Cost File'!$A$2:$A$31,0),MATCH(AZ$7,'SC Cost File'!$A$2:$AB$2,0))/COUNTIF($G$7:$CV$7,AZ$7)} -> 0 | BA42: {=INDEX('SC Cost File'!$A$2:$AB$31,MATCH($C42,'SC Cost File'!$A$2:$A$31,0),MATCH(BA$7,'SC Cost File'!$A$2:$AB$2,0))/COUNTIF($G$7:$CV$7,BA$7)} -> 0 | BB42: {=INDEX('SC Cost File'!$A$2:$AB$31,MATCH($C42,'SC Cost File'!$A$2:$A$31,0),MATCH(BB$7,'SC Cost File'!$A$2:$AB$2,0))/COUNTIF($G$7:$CV$7,BB$7)} -> 0 | BC42: {=INDEX('SC Cost File'!$A$2:$AB$31,MATCH($C42,'SC Cost File'!$A$2:$A$31,0),MATCH(BC$7,'SC Cost File'!$A$2:$AB$2,0))/COUNTIF($G$7:$CV$7,BC$7)} -> 0 | ... CV42: {=INDEX('SC Cost File'!$A$2:$AB$31,MATCH($C42,'SC Cost File'!$A$2:$A$31,0),MATCH(CV$7,'SC Cost File'!$A$2:$AB$2,0))/COUNTIF($G$7:$CV$7,CV$7)} -> 0
...

Sheet CURRENT WEEK CASHFLOW FORECAST
D1: 1 | E1: =D1+1 -> 2 | F1: =E1+1 -> 3 | G1: =F1+1 -> 4 | H1: 5 | I1: =H1+1 -> 6 | J1: =I1+1 -> 7 | K1: =J1+1 -> 8 | L1: =K1+1 -> 9 | M1: =L1+1 -> 10 | N1: =M1+1 -> 11 | O1: =N1+1 -> 12 | P1: =O1+1 -> 13 | Q1: Post 13 Week>> | R1: =+P1+1 -> 14 | S1: =+R1+1 -> 15 | T1: =+S1+1 -> 16 | U1: =+T1+1 -> 17 | V1: =+U1+1 -> 18 | W1: =+V1+1 -> 19 | X1: =+W1+1 -> 20 | Y1: =+X1+1 -> 21 | Z1: =+Y1+1 -> 22 | ... AN1: =+AM1+1 -> 36
D2: ="Week"&" "&D1 -> Week 1 | E2: ="Week"&" "&E1 -> Week 2 | F2: ="Week"&" "&F1 -> Week 3 | G2: ="Week"&" "&G1 -> Week 4 | H2: ="Week"&" "&H1 -> Week 5 | I2: ="Week"&" "&I1 -> Week 6 | J2: ="Week"&" "&J1 -> Week 7 | K2: ="Week"&" "&K1 -> Week 8 | ... P2: ="Week"&" "&P1 -> Week 13 | R2: ="Week"&" "&S1 -> Week 15 | S2: ="Week"&" "&T1 -> Week 16 | T2: ="Week"&" "&U1 -> Week 17 | U2: ="Week"&" "&V1 -> Week 18 | V2: ="Week"&" "&W1 -> Week 19 | W2: ="Week"&" "&X1 -> Week 20 | X2: ="Week"&" "&Y1 -> Week 21 | Y2: ="Week"&" "&Z1 -> Week 22 | ... AN2: ="Week"&" "&AO1 -> Week
C3: Monday of week | D3: ='CURRENT FORECAST START DATE'!C4 -> 45971 | E3: =D3+7 -> 45978 | F3: =E3+7 -> 45985 | G3: =F3+7 -> 45992 | H3: =G3+7 -> 45999 | I3: =H3+7 -> 46006 | J3: =I3+7 -> 46013 | K3: =J3+7 -> 46020 | L3: =K3+7 -> 46027 | ... P3: =O3+7 -> 46055 | R3: =P3+7 -> 46062 | S3: =R3+7 -> 46069 | T3: =S3+7 -> 46076 | U3: =T3+7 -> 46083 | V3: =U3+7 -> 46090 | W3: =V3+7 -> 46097 | X3: =W3+7 -> 46104 | Y3: =X3+7 -> 46111 | Z3: =Y3+7 -> 46118 | ... AN3: =AM3+7 -> 46216
B4: OPERATING CASH INFLOWS
B5: Operating Cash Receipts
B6: Customer Cash Receipts from A/R | C6: AR Aging | D6: 9000 | F6: 32000 | H6: 80000 | J6: 96000 | L6: 140000 | N6: 160000 | P6: 180000 | S6: 200000 | U6: 220000 | W6: 240000 | Y6: 260000 | AA6: 260000 | AC6: 260000 | AE6: 286957 | AG6: 286957 | AH6: =AF6 -> 0 | AI6: 286957 | AJ6: =AH6 -> 0 | AK6: =AI6 -> 286957 | AL6: =AJ6 -> 0 | AM6: =AK6 -> 286957 | AN6: =AL6 -> 0
B7: Customer Forecasted Receipts from Backlog | C7: AR (Backlog) | F7: 0 | G7: 0 | H7: 0 | I7: 0 | J7: 0 | K7: 0 | L7: 0 | M7: 0 | N7: 0 | O7: 0 | P7: 0 | R7: 0 | S7: 0 | T7: 0 | X7: 0 | Y7: 0 | Z7: 0 | AA7: 0 | AB7: 0 | AC7: 0 | AD7: 0 | AE7: 0 | AF7: 0 | AG7: 0 | AH7: 0 | AI7: 0 | AJ7: 0 | AK7: 0 | AL7: 0 | AM7: 0 | AN7: 0
B8: Customer Forecasted Receipts from Sales Forecast | C8: AR (Sales Forecast) | D8: =56952 -> 56952 | E8: 43968 | F8: 5763 | H8: 50000 | I8: 0 | J8: 0 | K8: 30000 | M8: 0 | O8: 0 | P8: 330000 | U8: 130000 | V8: 0 | W8: 0 | X8: 0 | Y8: 0 | Z8: 180000 | AA8: 0 | AB8: 0 | AC8: 0 | AD8: 230000 | AE8: 0 | AF8: 0 | AG8: 0 | AH8: 30000 | AK8: 1200000
B9: Other, non-customer related inflows | C9: Varies | D9: 0 | E9: 0 | F9: 0 | G9: 0 | H9: 0 | I9: 0 | J9: 0
B10: TOTAL INCOMING CASH | D10: =SUM(D6:D9) -> 65952 | E10: =SUM(E6:E9) -> 43968 | F10: =SUM(F6:F9) -> 37763 | G10: =SUM(G6:G9) -> 0 | H10: =SUM(H6:H9) -> 130000 | I10: =SUM(I6:I9) -> 0 | J10: =SUM(J6:J9) -> 96000 | K10: =SUM(K6:K9) -> 30000 | ... P10: =SUM(P6:P9) -> 510000 | R10: =SUM(R6:R9) -> 0 | S10: =SUM(S6:S9) -> 200000 | T10: =SUM(T6:T9) -> 0 | U10: =SUM(U6:U9) -> 350000 | V10: =SUM(V6:V9) -> 0 | W10: =SUM(W6:W9) -> 240000 | X10: =SUM(X6:X9) -> 0 | Y10: =SUM(Y6:Y9) -> 260000 | ... AN10: =SUM(AN6:AN9) -> 0
B12: OPERATING CASH DISBURSEMENTS
B13: Must Pays
B14: Labor | C14: Biweekly Payroll | D14: {=INDEX('Weekly Spend'!$F$86:$CV$94,MATCH($B14,'Weekly Spend'!$F$86:$F$94,0),MATCH(D$3,'Weekly Spend'!$F$86:$CV$86,0))} -> 0 | F14: {=INDEX('Weekly Spend'!$F$86:$CV$94,MATCH($B14,'Weekly Spend'!$F$86:$F$94,0),MATCH(F$3,'Weekly Spend'!$F$86:$CV$86,0))} -> 4500 | G14: {=INDEX('Weekly Spend'!$F$86:$CV$94,MATCH($B14,'Weekly Spend'!$F$86:$F$94,0),MATCH(G$3,'Weekly Spend'!$F$86:$CV$86,0))} -> 98566.692 | H14: {=INDEX('Weekly Spend'!$F$86:$CV$94,MATCH($B14,'Weekly Spend'!$F$86:$F$94,0),MATCH(H$3,'Weekly Spend'!$F$86:$CV$86,0))} -> 0 | I14: {=INDEX('Weekly Spend'!$F$86:$CV$94,MATCH($B14,'Weekly Spend'!$F$86:$F$94,0),MATCH(I$3,'Weekly Spend'!$F$86:$CV$86,0))} -> 93566.692 | J14: {=INDEX('Weekly Spend'!$F$86:$CV$94,MATCH($B14,'Weekly Spend'!$F$86:$F$94,0),MATCH(J$3,'Weekly Spend'!$F$86:$CV$86,0))} -> 0 | K14: {=INDEX('Weekly Spend'!$F$86:$CV$94,MATCH($B14,'Weekly Spend'!$F$86:$F$94,0),MATCH(K$3,'Weekly Spend'!$F$86:$CV$86,0))} -> 92316.692 | L14: {=INDEX('Weekly Spend'!$F$86:$CV$94,MATCH($B14,'Weekly Spend'!$F$86:$F$94,0),MATCH(L$3,'Weekly Spend'!$F$86:$CV$86,0))} -> 0 | M14: {=INDEX('Weekly Spend'!$F$86:$CV$94,MATCH($B14,'Weekly Spend'!$F$86:$F$94,0),MATCH(M$3,'Weekly Spend'!$F$86:$CV$86,0))} -> 90816.692 | ... P14: {=INDEX('Weekly Spend'!$F$86:$CV$94,MATCH($B14,'Weekly Spend'!$F$86:$F$94,0),MATCH(P$3,'Weekly Spend'!$F$86:$CV$86,0))} -> 0 | R14: {=INDEX('Weekly Spend'!$F$86:$CV$94,MATCH($B14,'Weekly Spend'!$F$86:$F$94,0),MATCH(R$3,'Weekly Spend'!$F$86:$CV$86,0))} -> 103716.69 | S14: {=INDEX('Weekly Spend'!$F$86:$CV$94,MATCH($B14,'Weekly Spend'!$F$86:$F$94,0),MATCH(S$3,'Weekly Spend'!$F$86:$CV$86,0))} -> 0 | T14: {=INDEX('Weekly Spend'!$F$86:$CV$94,MATCH($B14,'Weekly Spend'!$F$86:$F$94,0),MATCH(T$3,'Weekly Spend'!$F$86:$CV$86,0))} -> 100813.69 | U14: {=INDEX('Weekly Spend'!$F$86:$CV$94,MATCH($B14,'Weekly Spend'!$F$86:$F$94,0),MATCH(U$3,'Weekly Spend'!$F$86:$CV$86,0))} -> 0 | V14: {=INDEX('Weekly Spend'!$F$86:$CV$94,MATCH($B14,'Weekly Spend'!$F$86:$F$94,0),MATCH(V$3,'Weekly Spend'!$F$86:$CV$86,0))} -> 91813.692 | W14: {=INDEX('Weekly Spend'!$F$86:$CV$94,MATCH($B14,'Weekly Spend'!$F$86:$F$94,0),MATCH(W$3,'Weekly Spend'!$F$86:$CV$86,0))} -> 0 | X14: {=INDEX('Weekly Spend'!$F$86:$CV$94,MATCH($B14,'Weekly Spend'!$F$86:$F$94,0),MATCH(X$3,'Weekly Spend'!$F$86:$CV$86,0))} -> 100813.69 | Y14: {=INDEX('Weekly Spend'!$F$86:$CV$94,MATCH($B14,'Weekly Spend'!$F$86:$F$94,0),MATCH(Y$3,'Weekly Spend'!$F$86:$CV$86,0))} -> 0 | ... AN14: {=INDEX('Weekly Spend'!$F$86:$CV$94,MATCH($B14,'Weekly Spend'!$F$86:$F$94,0),MATCH(AN$3,'Weekly Spend'!$F$86:$CV$86,0))} -> 91716.692
B15: OpEx | C15: Invoices | D15: {=INDEX('Weekly Spend'!$F$86:$CV$94,MATCH($B15,'Weekly Spend'!$F$86:$F$94,0),MATCH(D$3,'Weekly Spend'!$F$86:$CV$86,0))} -> 5505.8 | E15: {=INDEX('Weekly Spend'!$F$86:$CV$94,MATCH($B15,'Weekly Spend'!$F$86:$F$94,0),MATCH(E$3,'Weekly Spend'!$F$86:$CV$86,0))} -> 5287 | F15: {=INDEX('Weekly Spend'!$F$86:$CV$94,MATCH($B15,'Weekly Spend'!$F$86:$F$94,0),MATCH(F$3,'Weekly Spend'!$F$86:$CV$86,0))} -> 20097.5 | G15: {=INDEX('Weekly Spend'!$F$86:$CV$94,MATCH($B15,'Weekly Spend'!$F$86:$F$94,0),MATCH(G$3,'Weekly Spend'!$F$86:$CV$86,0))} -> 67163 | H15: =INDEX('Weekly Spend'!$F$86:$CV$94,MATCH($B15,'Weekly Spend'!$F$86:$F$94,0),MATCH(H$3,'Weekly Spend'!$F$86:$CV$86,0)) -> 4500 | I15: {=INDEX('Weekly Spend'!$F$86:$CV$94,MATCH($B15,'Weekly Spend'!$F$86:$F$94,0),MATCH(I$3,'Weekly Spend'!$F$86:$CV$86,0))} -> 14500 | J15: {=INDEX('Weekly Spend'!$F$86:$CV$94,MATCH($B15,'Weekly Spend'!$F$86:$F$94,0),MATCH(J$3,'Weekly Spend'!$F$86:$CV$86,0))} -> 54500 | K15: {=INDEX('Weekly Spend'!$F$86:$CV$94,MATCH($B15,'Weekly Spend'!$F$86:$F$94,0),MATCH(K$3,'Weekly Spend'!$F$86:$CV$86,0))} -> 26500 | L15: {=INDEX('Weekly Spend'!$F$86:$CV$94,MATCH($B15,'Weekly Spend'!$F$86:$F$94,0),MATCH(L$3,'Weekly Spend'!$F$86:$CV$86,0))} -> 44906.25 | M15: {=INDEX('Weekly Spend'!$F$86:$CV$94,MATCH($B15,'Weekly Spend'!$F$86:$F$94,0),MATCH(M$3,'Weekly Spend'!$F$86:$CV$86,0))} -> 4906.25 | N15: {=INDEX('Weekly Spend'!$F$86:$CV$94,MATCH($B15,'Weekly Spend'!$F$86:$F$94,0),MATCH(N$3,'Weekly Spend'!$F$86:$CV$86,0))} -> 24906.25 | O15: {=INDEX('Weekly Spend'!$F$86:$CV$94,MATCH($B15,'Weekly Spend'!$F$86:$F$94,0),MATCH(O$3,'Weekly Spend'!$F$86:$CV$86,0))} -> 26906.25 | P15: {=INDEX('Weekly Spend'!$F$86:$CV$94,MATCH($B15,'Weekly Spend'!$F$86:$F$94,0),MATCH(P$3,'Weekly Spend'!$F$86:$CV$86,0))} -> 49625 | R15: {=INDEX('Weekly Spend'!$F$86:$CV$94,MATCH($B15,'Weekly Spend'!$F$86:$F$94,0),MATCH(R$3,'Weekly Spend'!$F$86:$CV$86,0))} -> 4625 | S15: {=INDEX('Weekly Spend'!$F$86:$CV$94,MATCH($B15,'Weekly Spend'!$F$86:$F$94,0),MATCH(S$3,'Weekly Spend'!$F$86:$CV$86,0))} -> 4625 | T15: {=INDEX('Weekly Spend'!$F$86:$CV$94,MATCH($B15,'Weekly Spend'!$F$86:$F$94,0),MATCH(T$3,'Weekly Spend'!$F$86:$CV$86,0))} -> 46625 | U15: {=INDEX('Weekly Spend'!$F$86:$CV$94,MATCH($B15,'Weekly Spend'!$F$86:$F$94,0),MATCH(U$3,'Weekly Spend'!$F$86:$CV$86,0))} -> 47940.8 | V15: {=INDEX('Weekly Spend'!$F$86:$CV$94,MATCH($B15,'Weekly Spend'!$F$86:$F$94,0),MATCH(V$3,'Weekly Spend'!$F$86:$CV$86,0))} -> 7940.8 | W15: {=INDEX('Weekly Spend'!$F$86:$CV$94,MATCH($B15,'Weekly Spend'!$F$86:$F$94,0),MATCH(W$3,'Weekly Spend'!$F$86:$CV$86,0))} -> 7940.8 | X15: {=INDEX('Weekly Spend'!$F$86:$CV$94,MATCH($B15,'Weekly Spend'!$F$86:$F$94,0),MATCH(X$3,'Weekly Spend'!$F$86:$CV$86,0))} -> 7940.8 | Y15: {=INDEX('Weekly Spend'!$F$86:$CV$94,MATCH($B15,'Weekly Spend'!$F$86:$F$94,0),MATCH(Y$3,'Weekly Spend'!$F$86:$CV$86,0))} -> 39940.8 | ... AN15: {=INDEX('Weekly Spend'!$F$86:$CV$94,MATCH($B15,'Weekly Spend'!$F$86:$F$94,0),MATCH(AN$3,'Weekly Spend'!$F$86:$CV$86,0))} -> 7245
